Workbook

Sheet Resumen Global
A1: CONTROL DE VALIDACIÓN · abril 2026 · Transactiva 2000 S.L.
A2: Fusión de validaciones 3.0TD + 2.0TD. APROBAR ≥30% · REVISAR 20–30% · RECHAZAR <20%. Detalle de cada factura en sus pestañas.
A4: Tarifa | B4: Nº facturas | C4: APROBAR | D4: REVISAR | E4: RECHAZAR | F4: Pestaña detalle
A5: 3.0TD | B5: =COUNTA('Resumen 3.0TD'!A5:A300) -> 28 | C5: =COUNTIF('Resumen 3.0TD'!F:F,"APROBAR") -> 7 | D5: =COUNTIF('Resumen 3.0TD'!F:F,"REVISAR") -> 8 | E5: =COUNTIF('Resumen 3.0TD'!F:F,"RECHAZAR") -> 12 | F5: Detalle 3.0TD
A6: 2.0TD | B6: =COUNTA('Resumen 2.0TD'!A5:A300) -> 136 | C6: =COUNTIF('Resumen 2.0TD'!F:F,"APROBAR") -> 60 | D6: =COUNTIF('Resumen 2.0TD'!F:F,"REVISAR") -> 27 | E6: =COUNTIF('Resumen 2.0TD'!F:F,"RECHAZAR") -> 49 | F6: Detalle 2.0TD
A7: TOTAL | B7: =SUM(B5:B6) -> 164 | C7: =SUM(C5:C6) -> 67 | D7: =SUM(D5:D6) -> 35 | E7: =SUM(E5:E6) -> 61

Sheet Resumen 3.0TD
A1: RESUMEN · 27 facturas 3.0TD · abril 2026 · margen abril vivo (editable) + histórico del CUPS (HOJA TTVA LUZ)
A2: LEYENDA | B2: APROBAR ≥30% | D2: REVISAR 20–30% | F2: RECHAZAR <20% · margen objetivo editable en Detalle
A4: Factura | B4: Cliente | C4: Nombre | D4: Prov. | E4: Margen abril | F4: Veredicto | G4: Margen hist. | H4: Cobrado hist. | I4: Qué revisar
A5: 8544 | B5: C02330 | C5: ORENCO 2019, S.L. | D5: Naturgy | E5: ='Detalle 3.0TD'!B17 -> 0.17898769 | F5: =IF('Detalle 3.0TD'!B17>=0.3,"APROBAR",IF('Detalle 3.0TD'!B17>=0.2,"REVISAR","RECHAZAR")) -> RECHAZAR | G5: 0.275 | H5: 40716.44 | I5: =IF('Detalle 3.0TD'!B17>=0.3,"OK · registrar",IF('Detalle 3.0TD'!B17>=0.2,"Margen abril <30%","Margen abril <20% · subir objetivo o renegociar"))&"" -> Margen abril <20% · subir objetivo o renegociar
A6: 8545 | B6: C01200 | C6: SOLUCIONES GASTRONÓMICAS DE JAVEA 2014, S.L. | D6: Naturgy | E6: ='Detalle 3.0TD'!B35 -> 0.20960183 | F6: =IF('Detalle 3.0TD'!B35>=0.3,"APROBAR",IF('Detalle 3.0TD'!B35>=0.2,"REVISAR","RECHAZAR")) -> REVISAR | G6: 0.244 | H6: 53718.09 | I6: =IF('Detalle 3.0TD'!B35>=0.3,"OK · registrar",IF('Detalle 3.0TD'!B35>=0.2,"Margen abril <30%","Margen abril <20% · subir objetivo o renegociar"))&"" -> Margen abril <30%
A7: 8546 | B7: C03270 | C7: LULU BEACH CLUB JAVEA SL | D7: Naturgy | E7: ='Detalle 3.0TD'!B53 -> 0.033690116 | F7: =IF('Detalle 3.0TD'!B53>=0.3,"APROBAR",IF('Detalle 3.0TD'!B53>=0.2,"REVISAR","RECHAZAR")) -> RECHAZAR | G7: 0.204 | H7: 12272.46 | I7: =IF('Detalle 3.0TD'!B53>=0.3,"OK · registrar",IF('Detalle 3.0TD'!B53>=0.2,"Margen abril <30%","Margen abril <20% · subir objetivo o renegociar"))&"" -> Margen abril <20% · subir objetivo o renegociar
A8: 8547 | B8: C01770 | C8: CASA LILI JAVEA, S.L. | D8: ? | E8: ='Detalle 3.0TD'!B72 -> 0.30715088 | F8: =IF('Detalle 3.0TD'!B72>=0.3,"APROBAR",IF('Detalle 3.0TD'!B72>=0.2,"REVISAR","RECHAZAR")) -> APROBAR | G8: 0.432 | H8: 130568.72 | I8: =IF('Detalle 3.0TD'!B72>=0.3,"OK · registrar",IF('Detalle 3.0TD'!B72>=0.2,"Margen abril <30%","Margen abril <20% · subir objetivo o renegociar"))&" · Es 6.1TD (no 3.0TD)" -> OK · registrar · Es 6.1TD (no 3.0TD)
A9: 8564 | B9: C01930 | C9: FUNDACIÓN FSU PROGRAMAS INTERNACIONALES | D9: Naturgy | E9: ='Detalle 3.0TD'!B90 -> 0.35858241 | F9: =IF('Detalle 3.0TD'!B90>=0.3,"APROBAR",IF('Detalle 3.0TD'!B90>=0.2,"REVISAR","RECHAZAR")) -> APROBAR | G9: 0.269 | H9: 18857.1 | I9: =IF('Detalle 3.0TD'!B90>=0.3,"OK · registrar",IF('Detalle 3.0TD'!B90>=0.2,"Margen abril <30%","Margen abril <20% · subir objetivo o renegociar"))&"" -> OK · registrar
A10: 8565 | B10: C01920 | C10: FUNDACIÓN FSU PROGRAMAS INTERNACIONALES | D10: Naturgy | E10: ='Detalle 3.0TD'!B108 -> 0.33436081 | F10: =IF('Detalle 3.0TD'!B108>=0.3,"APROBAR",IF('Detalle 3.0TD'!B108>=0.2,"REVISAR","RECHAZAR")) -> APROBAR | G10: 0.324 | H10: 19336.5 | I10: =IF('Detalle 3.0TD'!B108>=0.3,"OK · registrar",IF('Detalle 3.0TD'!B108>=0.2,"Margen abril <30%","Margen abril <20% · subir objetivo o renegociar"))&"" -> OK · registrar
A11: 8566 | B11: C01910 | C11: FUNDACIÓN FSU PROGRAMAS INTERNACIONALES | D11: Naturgy | E11: ='Detalle 3.0TD'!B126 -> 0.32661503 | F11: =IF('Detalle 3.0TD'!B126>=0.3,"APROBAR",IF('Detalle 3.0TD'!B126>=0.2,"REVISAR","RECHAZAR")) -> APROBAR | G11: 0.342 | H11: 10564.26 | I11: =IF('Detalle 3.0TD'!B126>=0.3,"OK · registrar",IF('Detalle 3.0TD'!B126>=0.2,"Margen abril <30%","Margen abril <20% · subir objetivo o renegociar"))&"" -> OK · registrar
A12: 8567 | B12: C00790 | C12: CASA LILI, S.L. | D12: Naturgy | E12: ='Detalle 3.0TD'!B145 -> 0.16289997 | F12: =IF('Detalle 3.0TD'!B145>=0.3,"APROBAR",IF('Detalle 3.0TD'!B145>=0.2,"REVISAR","RECHAZAR")) -> RECHAZAR | G12: 0.405 | H12: 151868.44 | I12: =IF('Detalle 3.0TD'!B145>=0.3,"OK · registrar",IF('Detalle 3.0TD'!B145>=0.2,"Margen abril <30%","Margen abril <20% · subir objetivo o renegociar"))&"" -> Margen abril <20% · subir objetivo o renegociar
A13: 8578 | B13: C02180 | C13: EDWIN BAUMGARTNER | D13: Naturgy | E13: ='Detalle 3.0TD'!B163 -> 0.30823789 | F13: =IF('Detalle 3.0TD'!B163>=0.3,"APROBAR",IF('Detalle 3.0TD'!B163>=0.2,"REVISAR","RECHAZAR")) -> APROBAR | G13: 0.487 | H13: 2907.71 | I13: =IF('Detalle 3.0TD'!B163>=0.3,"OK · registrar",IF('Detalle 3.0TD'!B163>=0.2,"Margen abril <30%","Margen abril <20% · subir objetivo o renegociar"))&"" -> OK · registrar
A14: 8615 | B14: C01220 | C14: VIVES ELECTRODOMÉSTICOS, S.L. | D14: Repsol | E14: ='Detalle 3.0TD'!B181 -> 0.13307223 | F14: =IF('Detalle 3.0TD'!B181>=0.3,"APROBAR",IF('Detalle 3.0TD'!B181>=0.2,"REVISAR","RECHAZAR")) -> RECHAZAR | G14: 0.316 | H14: 26924.82 | I14: =IF('Detalle 3.0TD'!B181>=0.3,"OK · registrar",IF('Detalle 3.0TD'!B181>=0.2,"Margen abril <30%","Margen abril <20% · subir objetivo o renegociar"))&" · Repsol margen muy bajo" -> Margen abril <20% · subir objetivo o renegociar · Repsol margen muy bajo
A15: 8629 | B15: C01510 | C15: CAFE ZUR BACKSTUBE, S.L. | D15: Naturgy | E15: ='Detalle 3.0TD'!B199 -> 0.29787383 | F15: =IF('Detalle 3.0TD'!B199>=0.3,"APROBAR",IF('Detalle 3.0TD'!B199>=0.2,"REVISAR","RECHAZAR")) -> REVISAR | G15: 0.362 | H15: 6192.61 | I15: =IF('Detalle 3.0TD'!B199>=0.3,"OK · registrar",IF('Detalle 3.0TD'!B199>=0.2,"Margen abril <30%","Margen abril <20% · subir objetivo o renegociar"))&"" -> Margen abril <30%
A16: 8635 | B16: C01630 | C16: ALEJANDRO BOX CANDELA | D16: Naturgy | E16: ='Detalle 3.0TD'!B217 -> 0.16804865 | F16: =IF('Detalle 3.0TD'!B217>=0.3,"APROBAR",IF('Detalle 3.0TD'!B217>=0.2,"REVISAR","RECHAZAR")) -> RECHAZAR | G16: 0.277 | H16: 31335.42 | I16: =IF('Detalle 3.0TD'!B217>=0.3,"OK · registrar",IF('Detalle 3.0TD'!B217>=0.2,"Margen abril <30%","Margen abril <20% · subir objetivo o renegociar"))&"" -> Margen abril <20% · subir objetivo o renegociar
A17: 8638 | B17: C01710 | C17: FARMACIA ESPINÓS | D17: Repsol | E17: ='Detalle 3.0TD'!B235 -> 0.16678386 | F17: =IF('Detalle 3.0TD'!B235>=0.3,"APROBAR",IF('Detalle 3.0TD'!B235>=0.2,"REVISAR","RECHAZAR")) -> RECHAZAR | G17: 0.253 | H17: 14704.48 | I17: =IF('Detalle 3.0TD'!B235>=0.3,"OK · registrar",IF('Detalle 3.0TD'!B235>=0.2,"Margen abril <30%","Margen abril <20% · subir objetivo o renegociar"))&"" -> Margen abril <20% · subir objetivo o renegociar
A18: 8644 | B18: C01840 | C18: JOSE GUILLERMO CHOLBI SART | D18: Naturgy | E18: ='Detalle 3.0TD'!B253 -> 0.33509687 | F18: =IF('Detalle 3.0TD'!B253>=0.3,"APROBAR",IF('Detalle 3.0TD'!B253>=0.2,"REVISAR","RECHAZAR")) -> APROBAR | G18: 0.184 | H18: 3367.63 | I18: =IF('Detalle 3.0TD'!B253>=0.3,"OK · registrar",IF('Detalle 3.0TD'!B253>=0.2,"Margen abril <30%","Margen abril <20% · subir objetivo o renegociar"))&"" -> OK · registrar
A19: 8649 | B19: C01980 | C19: TINTORERÍA LAVANDERÍA COLOMER | D19: Repsol | E19: ='Detalle 3.0TD'!B271 -> 0.21949185 | F19: =IF('Detalle 3.0TD'!B271>=0.3,"APROBAR",IF('Detalle 3.0TD'!B271>=0.2,"REVISAR","RECHAZAR")) -> REVISAR | G19: 0.203 | H19: 15417.71 | I19: =IF('Detalle 3.0TD'!B271>=0.3,"OK · registrar",IF('Detalle 3.0TD'!B271>=0.2,"Margen abril <30%","Margen abril <20% · subir objetivo o renegociar"))&" · P6 a precio doble (real)" -> Margen abril <30% · P6 a precio doble (real)
A20: 8652 | B20: C02180 | C20: EDWIN BAUMGARTNER | D20: Naturgy | E20: ='Detalle 3.0TD'!B289 -> 0.30823789 | F20: =IF('Detalle 3.0TD'!B289>=0.3,"APROBAR",IF('Detalle 3.0TD'!B289>=0.2,"REVISAR","RECHAZAR")) -> APROBAR | G20: 0.487 | H20: 2907.71 | I20: =IF('Detalle 3.0TD'!B289>=0.3,"OK · registrar",IF('Detalle 3.0TD'!B289>=0.2,"Margen abril <30%","Margen abril <20% · subir objetivo o renegociar"))&"" -> OK · registrar
A21: 8669 | B21: C02600 | C21: CRISTIAN FERRARI | D21: Naturgy | E21: ='Detalle 3.0TD'!B307 -> 0.2360357 | F21: =IF('Detalle 3.0TD'!B307>=0.3,"APROBAR",IF('Detalle 3.0TD'!B307>=0.2,"REVISAR","RECHAZAR")) -> REVISAR | G21: 0.292 | H21: 5897.71 | I21: =IF('Detalle 3.0TD'!B307>=0.3,"OK · registrar",IF('Detalle 3.0TD'!B307>=0.2,"Margen abril <30%","Margen abril <20% · subir objetivo o renegociar"))&"" -> Margen abril <30%
A22: 8684 | B22: C02910 | C22: NICHOLAS JAMES RATCLIFFE | D22: Repsol | E22: ='Detalle 3.0TD'!B325 -> 0.25181786 | F22: =IF('Detalle 3.0TD'!B325>=0.3,"APROBAR",IF('Detalle 3.0TD'!B325>=0.2,"REVISAR","RECHAZAR")) -> REVISAR | G22: 0.424 | H22: 4741.93 | I22: =IF('Detalle 3.0TD'!B325>=0.3,"OK · registrar",IF('Detalle 3.0TD'!B325>=0.2,"Margen abril <30%","Margen abril <20% · subir objetivo o renegociar"))&"" -> Margen abril <30%
A23: 8691 | B23: C03020 | C23: MONTGO SEGURIDAD S.L. | D23: Repsol | E23: ='Detalle 3.0TD'!B343 -> 0.07172886 | F23: =IF('Detalle 3.0TD'!B343>=0.3,"APROBAR",IF('Detalle 3.0TD'!B343>=0.2,"REVISAR","RECHAZAR")) -> RECHAZAR | G23: 0.154 | H23: 2756.73 | I23: =IF('Detalle 3.0TD'!B343>=0.3,"OK · registrar",IF('Detalle 3.0TD'!B343>=0.2,"Margen abril <30%","Margen abril <20% · subir objetivo o renegociar"))&"" -> Margen abril <20% · subir objetivo o renegociar
A24: 8705 | B24: C03200 | C24: 2 HANDS FULL, S.L | D24: Repsol | E24: ='Detalle 3.0TD'!B361 -> 0.069009331 | F24: =IF('Detalle 3.0TD'!B361>=0.3,"APROBAR",IF('Detalle 3.0TD'!B361>=0.2,"REVISAR","RECHAZAR")) -> RECHAZAR | G24: 0.147 | H24: 3844.21 | I24: =IF('Detalle 3.0TD'!B361>=0.3,"OK · registrar",IF('Detalle 3.0TD'!B361>=0.2,"Margen abril <30%","Margen abril <20% · subir objetivo o renegociar"))&"" -> Margen abril <20% · subir objetivo o renegociar
A25: 8731 | B25: C01500 | C25: SANTIAGO JAVIER NUÑEZ JOVER | D25: Repsol | E25: ='Detalle 3.0TD'!B379 -> 0.163502 | F25: =IF('Detalle 3.0TD'!B379>=0.3,"APROBAR",IF('Detalle 3.0TD'!B379>=0.2,"REVISAR","RECHAZAR")) -> RECHAZAR | G25: 0.306 | H25: 43740 | I25: =IF('Detalle 3.0TD'!B379>=0.3,"OK · registrar",IF('Detalle 3.0TD'!B379>=0.2,"Margen abril <30%","Margen abril <20% · subir objetivo o renegociar"))&" · P6 doble (real); abril sin consumo" -> Margen abril <20% · subir objetivo o renegociar · P6 doble (real); abril sin consumo
A26: 8732 | B26: C02430 | C26: CINDY DEPERE | D26: Naturgy | E26: ='Detalle 3.0TD'!B398 -> 0.26203771 | F26: =IF('Detalle 3.0TD'!B398>=0.3,"APROBAR",IF('Detalle 3.0TD'!B398>=0.2,"REVISAR","RECHAZAR")) -> REVISAR | G26: 0.31 | H26: 14442.13 | I26: =IF('Detalle 3.0TD'!B398>=0.3,"OK · registrar",IF('Detalle 3.0TD'!B398>=0.2,"Margen abril <30%","Margen abril <20% · subir objetivo o renegociar"))&" · Excedentes solares NO compensados" -> Margen abril <30% · Excedentes solares NO compensados
A27: 8733 | B27: C03410 | C27: NORAY PUERTO 2012 S.L. | D27: Naturgy | E27: ='Detalle 3.0TD'!B416 -> 0.18029709 | F27: =IF('Detalle 3.0TD'!B416>=0.3,"APROBAR",IF('Detalle 3.0TD'!B416>=0.2,"REVISAR","RECHAZAR")) -> RECHAZAR | G27: 0.326 | H27: 5854.69 | I27: =IF('Detalle 3.0TD'!B416>=0.3,"OK · registrar",IF('Detalle 3.0TD'!B416>=0.2,"Margen abril <30%","Margen abril <20% · subir objetivo o renegociar"))&"" -> Margen abril <20% · subir objetivo o renegociar
A28: 8734 | B28: C01820 | C28: PIZZERIA TIGER, S.L. | D28: Naturgy | E28: ='Detalle 3.0TD'!B434 -> 0.21443777 | F28: =IF('Detalle 3.0TD'!B434>=0.3,"APROBAR",IF('Detalle 3.0TD'!B434>=0.2,"REVISAR","RECHAZAR")) -> REVISAR | G28: 0.347 | H28: 33692.13 | I28: =IF('Detalle 3.0TD'!B434>=0.3,"OK · registrar",IF('Detalle 3.0TD'!B434>=0.2,"Margen abril <30%","Margen abril <20% · subir objetivo o renegociar"))&"" -> Margen abril <30%
A29: 8735 | B29: C02700 | C29: TALLERES MARTINEZ JAVEA SL | D29: Repsol | E29: ='Detalle 3.0TD'!B452 -> 0.047489346 | F29: =IF('Detalle 3.0TD'!B452>=0.3,"APROBAR",IF('Detalle 3.0TD'!B452>=0.2,"REVISAR","RECHAZAR")) -> RECHAZAR | G29: 0.129 | H29: 14832.89 | I29: =IF('Detalle 3.0TD'!B452>=0.3,"OK · registrar",IF('Detalle 3.0TD'!B452>=0.2,"Margen abril <30%","Margen abril <20% · subir objetivo o renegociar"))&"" -> Margen abril <20% · subir objetivo o renegociar
A30: 8737 | B30: C00740 | C30: PIZZERIA ORBA, S.L. | D30: Naturgy | E30: ='Detalle 3.0TD'!B470 -> 0.20018502 | F30: =IF('Detalle 3.0TD'!B470>=0.3,"APROBAR",IF('Detalle 3.0TD'!B470>=0.2,"REVISAR","RECHAZAR")) -> REVISAR | G30: 0.314 | H30: 82412.04 | I30: =IF('Detalle 3.0TD'!B470>=0.3,"OK · registrar",IF('Detalle 3.0TD'!B470>=0.2,"Margen abril <30%","Margen abril <20% · subir objetivo o renegociar"))&"" -> Margen abril <30%
A31: 8738 | B31: C02620 | C31: JAVEA PADEL & Tenis SL | D31: Naturgy | E31: ='Detalle 3.0TD'!B488 -> 0.16668595 | F31: =IF('Detalle 3.0TD'!B488>=0.3,"APROBAR",IF('Detalle 3.0TD'!B488>=0.2,"REVISAR","RECHAZAR")) -> RECHAZAR | G31: 0.324 | H31: 40860.13 | I31: =IF('Detalle 3.0TD'!B488>=0.3,"OK · registrar",IF('Detalle 3.0TD'!B488>=0.2,"Margen abril <30%","Margen abril <20% · subir objetivo o renegociar"))&"" -> Margen abril <20% · subir objetivo o renegociar
A33: Margen abril editable en TODAS (celda amarilla en Detalle). Margen hist., cobrado y mejor/peor mes vienen de HOJA TTVA LUZ por CUPS.

Sheet Detalle 3.0TD
A1: Factura 8544 · C02330 · ORENCO 2019, S.L. | I1: ES0021000001197056KH · Naturgy · 01/04/26 a 30/04/26 · PC real leído: 01MAR_31MAR26 (P2/P3/P6) + plan fijo | R1: HISTÓRICO DEL CUPS · HOJA TTVA LUZ
A2: Concepto | B2: PENDIENTE (sin registrar) | H2: MES ANTERIOR · Fact.6296 (01/03/26 a 31/03/26) | L2: AÑO ANTERIOR · Fact.4508 (01/04/25 a 30/04/25) | R2: Cobrado total: 40.716 €
B3: Cant | C3: Días | D3: PC real | E3: PV | F3: Importe | H3: Cant | I3: PV | J3: Importe | L3: Cant | M3: PV | N3: Importe | R3: Pagado total: 29.523 €
A4: P1 Potencia | B4: 30 | C4: 30 | D4: 1.73784 | E4: 2.5542 | F4: =ROUND(B4*E4,2) -> 76.63 | H4: 30 | I4: 2.5542 | J4: =ROUND(H4*I4,2) -> 76.63 | L4: 30 | M4: 2.5542 | N4: =ROUND(L4*M4,2) -> 76.63 | R4: DIF: 11.193 € · Margen hist.: 27.5%
A5: P2 Potencia | B5: 30 | C5: 30 | D5: 0.9357 | E5: 1.37733 | F5: =ROUND(B5*E5,2) -> 41.32 | H5: 30 | I5: 1.37733 | J5: =ROUND(H5*I5,2) -> 41.32 | L5: 30 | M5: 1.37733 | N5: =ROUND(L5*M5,2) -> 41.32 | R5: Mejor mes: 2024-06 · 3.014 € · margen 56%
A6: P3 Potencia | B6: 30 | C6: 30 | D6: 0.43137 | E6: 0.62868 | F6: =ROUND(B6*E6,2) -> 18.86 | H6: 30 | I6: 0.62868 | J6: =ROUND(H6*I6,2) -> 18.86 | L6: 30 | M6: 0.62868 | N6: =ROUND(L6*M6,2) -> 18.86 | R6: Peor mes: 2024-11 · 701 € · margen 39%
A7: P4 Potencia | B7: 30 | C7: 30 | D7: 0.38244 | E7: 0.5561 | F7: =ROUND(B7*E7,2) -> 16.68 | H7: 30 | I7: 0.5561 | J7: =ROUND(H7*I7,2) -> 16.68 | L7: 30 | M7: 0.5561 | N7: =ROUND(L7*M7,2) -> 16.68 | R7: ⚠ Consumo en P1/P2 (calendario inactivo) → consolidado a P4/P5/P6
A8: P5 Potencia | B8: 30 | C8: 30 | D8: 0.26964 | E8: 0.3868 | F8: =ROUND(B8*E8,2) -> 11.6 | H8: 30 | I8: 0.3868 | J8: =ROUND(H8*I8,2) -> 11.6 | L8: 30 | M8: 0.3868 | N8: =ROUND(L8*M8,2) -> 11.6 | R8: Importe mensual cobrado (€) · últimos 24 meses
A9: P6 Potencia | B9: 30 | C9: 30 | D9: 0.18156 | E9: 0.2653 | F9: =ROUND(B9*E9,2) -> 7.96 | H9: 30 | I9: 0.2653 | J9: =ROUND(H9*I9,2) -> 7.96 | L9: 30 | M9: 0.2653 | N9: =ROUND(L9*M9,2) -> 7.96
A10: P4 Energía | B10: =IF($P$10="",2517.101,ROUND(2517.101*((1087.3487/(1-$P$10))-173.05)/1151.35,2)) -> 2517.101 | D10: 0.121236 | E10: 0.139 | F10: =ROUND(B10*E10,2) -> 349.88 | H10: 2317.101 | I10: 0.139 | J10: =ROUND(H10*I10,2) -> 322.08 | L10: 1937.42 | M10: 0.145 | N10: =ROUND(L10*M10,2) -> 280.93 | O10: Margen objetivo (edita el % aquí) ▶
A11: P5 Energía | B11: =IF($P$10="",2364.265,ROUND(2364.265*((1087.3487/(1-$P$10))-173.05)/1151.35,2)) -> 2364.265 | D11: 0.114444 | E11: 0.138 | F11: =ROUND(B11*E11,2) -> 326.27 | H11: 2064.265 | I11: 0.138 | J11: =ROUND(H11*I11,2) -> 284.87 | L11: 1611.579 | M11: 0.139 | N11: =ROUND(L11*M11,2) -> 224.01 | O11: Cant. P4/P5/P6 suben en proporción
A12: P6 Energía | B12: =IF($P$10="",3683.741,ROUND(3683.741*((1087.3487/(1-$P$10))-173.05)/1151.35,2)) -> 3683.741 | D12: 0.106808 | E12: 0.129 | F12: =ROUND(B12*E12,2) -> 475.2 | H12: 3383.741 | I12: 0.129 | J12: =ROUND(H12*I12,2) -> 436.5 | L12: 2928.76 | M12: 0.139 | N12: =ROUND(L12*M12,2) -> 407.1 | O12: para cumplir ese margen
A13: Alquiler contador | B13: 1 | C13: 30 | D13: 17.615 | E13: 17.615 | F13: =ROUND(B13*E13,2) -> 17.62 | H13: 1 | I13: 17.615 | J13: =ROUND(H13*I13,2) -> 17.62 | L13: 1 | M13: 17.615 | N13: =ROUND(L13*M13,2) -> 17.62
A14: Bono social | B14: 30 | C14: 30 | D14: 0.01912 | E14: 0.01912 | F14: =ROUND(B14*E14,2) -> 0.57 | H14: 30 | I14: 0.01274 | J14: =ROUND(H14*I14,2) -> 0.38 | L14: 30 | M14: 0.01274 | N14: =ROUND(L14*M14,2) -> 0.38
A15: Tasa eléctrica | B15: 71.99 | D15: 1 | E15: 1 | F15: =ROUND(B15*E15,2) -> 71.99 | H15: 66.49 | I15: 1 | J15: =ROUND(H15*I15,2) -> 66.49 | L15: 62.66 | M15: 1 | N15: =ROUND(L15*M15,2) -> 62.66
A16: TOTAL c/IVA | F16: =ROUND((SUM(F4:F15)-F15)*1.21+F15,2) -> 1696.52 | J16: =ROUND((SUM(J4:J15)-J15)*1.21+J15,2) -> 1560.24 | N16: =ROUND((SUM(N4:N15)-N15)*1.21+N15,2) -> 1397.4
A17: MARGEN sin registrar | B17: =(SUM(F4:F12)-1087.3487)/SUM(F4:F12) -> 0.17898769 | L17: =IF(B17>=0.3,"APROBAR",IF(B17>=0.2,"REVISAR","RECHAZAR")) -> RECHAZAR
A19: Factura 8545 · C01200 · SOLUCIONES GASTRONÓMICAS DE JAVEA 2014, S.L. | I19: ES0021000001209594ZK · Naturgy · 01/04/26 a 30/04/26 · PC maestro (=factura real, verificado) | R19: HISTÓRICO DEL CUPS · HOJA TTVA LUZ
A20: Concepto | B20: PENDIENTE (sin registrar) | H20: MES ANTERIOR · Fact.6297 (01/03/26 a 31/03/26) | L20: AÑO ANTERIOR · Fact.4514 (01/04/25 a 30/04/25) | R20: Cobrado total: 53.718 €
B21: Cant | C21: Días | D21: PC real | E21: PV | F21: Importe | H21: Cant | I21: PV | J21: Importe | L21: Cant | M21: PV | N21: Importe | R21: Pagado total: 40.613 €
A22: P1 Potencia | B22: 17.32 | C22: 30 | D22: 1.73784 | E22: 1.999 | F22: =ROUND(B22*E22,2) -> 34.62 | H22: 17.32 | I22: 1.999 | J22: =ROUND(H22*I22,2) -> 34.62 | L22: 17.32 | M22: 2.5542 | N22: =ROUND(L22*M22,2) -> 44.24 | R22: DIF: 13.105 € · Margen hist.: 24.4%
A23: P2 Potencia | B23: 17.32 | C23: 30 | D23: 0.9357 | E23: 1.811 | F23: =ROUND(B23*E23,2) -> 31.37 | H23: 17.32 | I23: 1.811 | J23: =ROUND(H23*I23,2) -> 31.37 | L23: 17.32 | M23: 1.3773 | N23: =ROUND(L23*M23,2) -> 23.85 | R23: Mejor mes: 2024-08 · 2.606 € · margen 23%
A24: P3 Potencia | B24: 17.32 | C24: 30 | D24: 0.43137 | E24: 0.6161 | F24: =ROUND(B24*E24,2) -> 10.67 | H24: 17.32 | I24: 0.6161 | J24: =ROUND(H24*I24,2) -> 10.67 | L24: 17.32 | M24: 0.6286 | N24: =ROUND(L24*M24,2) -> 10.89 | R24: Peor mes: 2023-01 · 446 € · margen 25%
A25: P4 Potencia | B25: 17.32 | C25: 30 | D25: 0.38244 | E25: 0.5551 | F25: =ROUND(B25*E25,2) -> 9.61 | H25: 17.32 | I25: 0.5551 | J25: =ROUND(H25*I25,2) -> 9.61 | L25: 17.32 | M25: 0.5561 | N25: =ROUND(L25*M25,2) -> 9.63 | R25: ⚠ Consumo en P1/P2 (calendario inactivo) → consolidado a P4/P5/P6
A26: P5 Potencia | B26: 17.32 | C26: 30 | D26: 0.26964 | E26: 0.595 | F26: =ROUND(B26*E26,2) -> 10.31 | H26: 17.32 | I26: 0.595 | J26: =ROUND(H26*I26,2) -> 10.31 | L26: 17.32 | M26: 0.3868 | N26: =ROUND(L26*M26,2) -> 6.7 | R26: Importe mensual cobrado (€) · últimos 24 meses
A27: P6 Potencia | B27: 17.32 | C27: 30 | D27: 0.18156 | E27: 0.4523 | F27: =ROUND(B27*E27,2) -> 7.83 | H27: 17.32 | I27: 0.4523 | J27: =ROUND(H27*I27,2) -> 7.83 | L27: 17.32 | M27: 0.2653 | N27: =ROUND(L27*M27,2) -> 4.59
A28: P4 Energía | B28: =IF($P$28="",1691.432,ROUND(1691.432*((803.9614/(1-$P$28))-104.41)/912.75,2)) -> 1691.432 | D28: 0.121236 | E28: 0.149 | F28: =ROUND(B28*E28,2) -> 252.02 | H28: 1474.716 | I28: 0.15 | J28: =ROUND(H28*I28,2) -> 221.21 | L28: 1570.18 | M28: 0.16 | N28: =ROUND(L28*M28,2) -> 251.23 | O28: Margen objetivo (edita el % aquí) ▶
A29: P5 Energía | B29: =IF($P$28="",2156.035,ROUND(2156.035*((803.9614/(1-$P$28))-104.41)/912.75,2)) -> 2156.035 | D29: 0.114444 | E29: 0.14 | F29: =ROUND(B29*E29,2) -> 301.84 | H29: 1814.66 | I29: 0.149 | J29: =ROUND(H29*I29,2) -> 270.38 | L29: 1034.274 | M29: 0.155 | N29: =ROUND(L29*M29,2) -> 160.31 | O29: Cant. P4/P5/P6 suben en proporción
A30: P6 Energía | B30: =IF($P$28="",2658.43,ROUND(2658.43*((803.9614/(1-$P$28))-104.41)/912.75,2)) -> 2658.43 | D30: 0.106808 | E30: 0.135 | F30: =ROUND(B30*E30,2) -> 358.89 | H30: 2225.184 | I30: 0.139 | J30: =ROUND(H30*I30,2) -> 309.3 | L30: 2165.73 | M30: 0.135 | N30: =ROUND(L30*M30,2) -> 292.37 | O30: para cumplir ese margen
A31: Alquiler contador | B31: 1 | C31: 30 | D31: 17.615 | E31: 17.615 | F31: =ROUND(B31*E31,2) -> 17.62 | H31: 1 | I31: 17.615 | J31: =ROUND(H31*I31,2) -> 17.62 | L31: 1 | M31: 17.615 | N31: =ROUND(L31*M31,2) -> 17.62
A32: Bono social | B32: 5 | C32: 30 | D32: 0.01912 | E32: 0.01912 | F32: =ROUND(B32*E32,2) -> 0.1 | H32: 5 | I32: 0.01912 | J32: =ROUND(H32*I32,2) -> 0.1 | L32: 30 | M32: 0.01274 | N32: =ROUND(L32*M32,2) -> 0.38
A33: Tasa eléctrica | B33: 59.26 | D33: 1 | E33: 1 | F33: =ROUND(B33*E33,2) -> 59.26 | H33: 49.46 | I33: 1 | J33: =ROUND(H33*I33,2) -> 49.46 | L33: 44 | M33: 1 | N33: =ROUND(L33*M33,2) -> 44
A34: TOTAL c/IVA | F34: =ROUND((SUM(F22:F33)-F33)*1.21+F33,2) -> 1311.46 | J34: =ROUND((SUM(J22:J33)-J33)*1.21+J33,2) -> 1166.31 | N34: =ROUND((SUM(N22:N33)-N33)*1.21+N33,2) -> 1038.39
A35: MARGEN sin registrar | B35: =(SUM(F22:F30)-803.9614)/SUM(F22:F30) -> 0.20960183 | L35: =IF(B35>=0.3,"APROBAR",IF(B35>=0.2,"REVISAR","RECHAZAR")) -> REVISAR
A37: Factura 8546 · C03270 · LULU BEACH CLUB JAVEA SL | I37: ES0021000001205457LR · Naturgy · 01/04/26 a 30/04/26 · PC maestro (=factura real, verificado) | R37: HISTÓRICO DEL CUPS · HOJA TTVA LUZ
A38: Concepto | B38: PENDIENTE (sin registrar) | H38: MES ANTERIOR (s/d) | L38: AÑO ANTERIOR (s/d) | R38: Cobrado total: 12.272 €
B39: Cant | C39: Días | D39: PC real | E39: PV | F39: Importe | H39: Cant | I39: PV | J39: Importe | L39: Cant | M39: PV | N39: Importe | R39: Pagado total: 9.764 €
A40: P1 Potencia | B40: 37 | C40: 30 | D40: 1.73784 | E40: 1.74 | F40: =ROUND(B40*E40,2) -> 64.38 | R40: DIF: 2.509 € · Margen hist.: 20.4%
A41: P2 Potencia | B41: 37 | C41: 30 | D41: 0.9357 | E41: 0.94 | F41: =ROUND(B41*E41,2) -> 34.78 | R41: Mejor mes: 2026-05 · 3.747 € · margen 22%
A42: P3 Potencia | B42: 37 | C42: 30 | D42: 0.43137 | E42: 0.43 | F42: =ROUND(B42*E42,2) -> 15.91 | R42: Peor mes: 2026-02 · 1.625 € · margen 27%
...

Sheet Resumen 2.0TD
A1: RESUMEN 2.0TD · 136 facturas · abril 2026 · Transactiva 2000 S.L.
A2: APROBAR ≥30% · REVISAR 20–30% · RECHAZAR <20%. PC provisional (ámbar) → sustituir por real. Margen objetivo editable por factura en el Detalle.
A3: ⚙ OPTIMIZAR (converge al objetivo · freno mejor mes) ▶ | D3: OPTIMIZAR | E3: Margen obj. ▶ | F3: 0.3 | G3: Ganancia ▶ | H3: =SUM(K5:K140) -> 1508.5559
A4: Factura | B4: Cliente | C4: Nombre | D4: Prov. | E4: Margen abril | F4: Veredicto | G4: Margen hist. | H4: Cobrado hist. | I4: Qué revisar
A5: 8550 | B5: C02150 | C5: FUNDACIÓN FSU PROGRAMAS INTERNACIO | D5: Naturgy | E5: ='Detalle 2.0TD'!B15 -> 0.32906535 | F5: ='Detalle 2.0TD'!D15 -> APROBAR | G5: 0.2802 | H5: 2435.51 | I5: =IF('Detalle 2.0TD'!B15="","Falta PC real",IF('Detalle 2.0TD'!B15>=0.3,"OK · registrar",IF('Detalle 2.0TD'!B15>=0.2,"Revisar margen","Revisar PC/PV"))) -> OK · registrar | K5: ='Detalle 2.0TD'!AD15 -> -0.0079
A6: 8551 | B6: C02140 | C6: FUNDACIÓN FSU PROGRAMAS INTERNACIO | D6: Naturgy | E6: ='Detalle 2.0TD'!B29 -> 0.32791454 | F6: ='Detalle 2.0TD'!D29 -> APROBAR | G6: 0.2374 | H6: 2120.45 | I6: =IF('Detalle 2.0TD'!B29="","Falta PC real",IF('Detalle 2.0TD'!B29>=0.3,"OK · registrar",IF('Detalle 2.0TD'!B29>=0.2,"Revisar margen","Revisar PC/PV"))) -> OK · registrar | K6: ='Detalle 2.0TD'!AD29 -> 0.0041
A7: 8552 | B7: C02130 | C7: FUNDACIÓN FSU PROGRAMAS INTERNACIO | D7: Naturgy | E7: ='Detalle 2.0TD'!B43 -> 0.33776615 | F7: ='Detalle 2.0TD'!D43 -> APROBAR | G7: 0.3004 | H7: 3194.42 | I7: =IF('Detalle 2.0TD'!B43="","Falta PC real",IF('Detalle 2.0TD'!B43>=0.3,"OK · registrar",IF('Detalle 2.0TD'!B43>=0.2,"Revisar margen","Revisar PC/PV"))) -> OK · registrar | K7: ='Detalle 2.0TD'!AD43 -> -0.0057
A8: 8553 | B8: C02120 | C8: FUNDACIÓN FSU PROGRAMAS INTERNACIO | D8: Naturgy | E8: ='Detalle 2.0TD'!B57 -> 0.29999454 | F8: ='Detalle 2.0TD'!D57 -> REVISAR | G8: 0.2933 | H8: 2606.28 | I8: =IF('Detalle 2.0TD'!B57="","Falta PC real",IF('Detalle 2.0TD'!B57>=0.3,"OK · registrar",IF('Detalle 2.0TD'!B57>=0.2,"Revisar margen","Revisar PC/PV"))) -> Revisar margen | K8: ='Detalle 2.0TD'!AD57 -> 42.8272
A9: 8554 | B9: C02110 | C9: FUNDACIÓN FSU PROGRAMAS INTERNACIO | D9: Naturgy | E9: ='Detalle 2.0TD'!B71 -> 0.33884194 | F9: ='Detalle 2.0TD'!D71 -> APROBAR | G9: 0.3099 | H9: 5248.88 | I9: =IF('Detalle 2.0TD'!B71="","Falta PC real",IF('Detalle 2.0TD'!B71>=0.3,"OK · registrar",IF('Detalle 2.0TD'!B71>=0.2,"Revisar margen","Revisar PC/PV"))) -> OK · registrar | K9: ='Detalle 2.0TD'!AD71 -> 0.0028
A10: 8555 | B10: C02100 | C10: FUNDACIÓN FSU PROGRAMAS INTERNACIO | D10: Naturgy | E10: ='Detalle 2.0TD'!B85 -> 0.33604893 | F10: ='Detalle 2.0TD'!D85 -> APROBAR | G10: 0.3022 | H10: 1841.6 | I10: =IF('Detalle 2.0TD'!B85="","Falta PC real",IF('Detalle 2.0TD'!B85>=0.3,"OK · registrar",IF('Detalle 2.0TD'!B85>=0.2,"Revisar margen","Revisar PC/PV"))) -> OK · registrar | K10: ='Detalle 2.0TD'!AD85 -> 0.0048
A11: 8556 | B11: C02090 | C11: FUNDACIÓN FSU PROGRAMAS INTERNACIO | D11: Naturgy | E11: ='Detalle 2.0TD'!B99 -> 0.33892336 | F11: ='Detalle 2.0TD'!D99 -> APROBAR | G11: 0.2895 | H11: 2954.17 | I11: =IF('Detalle 2.0TD'!B99="","Falta PC real",IF('Detalle 2.0TD'!B99>=0.3,"OK · registrar",IF('Detalle 2.0TD'!B99>=0.2,"Revisar margen","Revisar PC/PV"))) -> OK · registrar | K11: ='Detalle 2.0TD'!AD99 -> 0.0107
A12: 8557 | B12: C02080 | C12: FUNDACIÓN FSU PROGRAMAS INTERNACIO | D12: Naturgy | E12: ='Detalle 2.0TD'!B113 -> 0.33246101 | F12: ='Detalle 2.0TD'!D113 -> APROBAR | I12: =IF('Detalle 2.0TD'!B113="","Falta PC real",IF('Detalle 2.0TD'!B113>=0.3,"OK · registrar",IF('Detalle 2.0TD'!B113>=0.2,"Revisar margen","Revisar PC/PV"))) -> OK · registrar | K12: ='Detalle 2.0TD'!AD113 -> -0.0057
A13: 8558 | B13: C02060 | C13: FUNDACIÓN FSU PROGRAMAS INTERNACIO | D13: Naturgy | E13: ='Detalle 2.0TD'!B127 -> 0.3356097 | F13: ='Detalle 2.0TD'!D127 -> APROBAR | G13: 0.293 | H13: 3233.11 | I13: =IF('Detalle 2.0TD'!B127="","Falta PC real",IF('Detalle 2.0TD'!B127>=0.3,"OK · registrar",IF('Detalle 2.0TD'!B127>=0.2,"Revisar margen","Revisar PC/PV"))) -> OK · registrar | K13: ='Detalle 2.0TD'!AD127 -> -0.0004
A14: 8559 | B14: C02040 | C14: FUNDACIÓN FSU PROGRAMAS INTERNACIO | D14: Naturgy | E14: ='Detalle 2.0TD'!B141 -> 0.32177702 | F14: ='Detalle 2.0TD'!D141 -> APROBAR | G14: 0.3314 | H14: 989.5 | I14: =IF('Detalle 2.0TD'!B141="","Falta PC real",IF('Detalle 2.0TD'!B141>=0.3,"OK · registrar",IF('Detalle 2.0TD'!B141>=0.2,"Revisar margen","Revisar PC/PV"))) -> OK · registrar | K14: ='Detalle 2.0TD'!AD141 -> 0.0104
A15: 8560 | B15: C02030 | C15: FUNDACIÓN FSU PROGRAMAS INTERNACIO | D15: Naturgy | E15: ='Detalle 2.0TD'!B155 -> 0.32654455 | F15: ='Detalle 2.0TD'!D155 -> APROBAR | G15: 0.2482 | H15: 837.32 | I15: =IF('Detalle 2.0TD'!B155="","Falta PC real",IF('Detalle 2.0TD'!B155>=0.3,"OK · registrar",IF('Detalle 2.0TD'!B155>=0.2,"Revisar margen","Revisar PC/PV"))) -> OK · registrar | K15: ='Detalle 2.0TD'!AD155 -> -0.0083
A16: 8561 | B16: C02020 | C16: FUNDACIÓN FSU PROGRAMAS INTERNACIO | D16: Naturgy | E16: ='Detalle 2.0TD'!B169 -> 0.33709853 | F16: ='Detalle 2.0TD'!D169 -> APROBAR | G16: 0.2981 | H16: 3102.69 | I16: =IF('Detalle 2.0TD'!B169="","Falta PC real",IF('Detalle 2.0TD'!B169>=0.3,"OK · registrar",IF('Detalle 2.0TD'!B169>=0.2,"Revisar margen","Revisar PC/PV"))) -> OK · registrar | K16: ='Detalle 2.0TD'!AD169 -> 0.0043
A17: 8562 | B17: C01970 | C17: FUNDACIÓN FSU PROGRAMAS INTERNACIO | D17: Naturgy | E17: ='Detalle 2.0TD'!B183 -> 0.3310343 | F17: ='Detalle 2.0TD'!D183 -> APROBAR | G17: 0.295 | H17: 2842.61 | I17: =IF('Detalle 2.0TD'!B183="","Falta PC real",IF('Detalle 2.0TD'!B183>=0.3,"OK · registrar",IF('Detalle 2.0TD'!B183>=0.2,"Revisar margen","Revisar PC/PV"))) -> OK · registrar | K17: ='Detalle 2.0TD'!AD183 -> 0.0005
A18: 8563 | B18: C01960 | C18: FUNDACIÓN FSU PROGRAMAS INTERNACIO | D18: Naturgy | E18: ='Detalle 2.0TD'!B197 -> 0.33306586 | F18: ='Detalle 2.0TD'!D197 -> APROBAR | G18: 0.3206 | H18: 3731.12 | I18: =IF('Detalle 2.0TD'!B197="","Falta PC real",IF('Detalle 2.0TD'!B197>=0.3,"OK · registrar",IF('Detalle 2.0TD'!B197>=0.2,"Revisar margen","Revisar PC/PV"))) -> OK · registrar | K18: ='Detalle 2.0TD'!AD197 -> -0.0037
A19: 8568 | B19: C01400 | C19: CHRISTOPH BLUME | D19: Naturgy | E19: ='Detalle 2.0TD'!B211 -> 0.29999905 | F19: ='Detalle 2.0TD'!D211 -> REVISAR | G19: 0.3031 | H19: 2280.53 | I19: =IF('Detalle 2.0TD'!B211="","Falta PC real",IF('Detalle 2.0TD'!B211>=0.3,"OK · registrar",IF('Detalle 2.0TD'!B211>=0.2,"Revisar margen","Revisar PC/PV"))) -> Revisar margen | K19: ='Detalle 2.0TD'!AD211 -> 16.5673
A20: 8569 | B20: C02560 | C20: PEDRO IVARS TRO 2018, S.L. | D20: Naturgy | E20: ='Detalle 2.0TD'!B230 -> 0.30001682 | F20: ='Detalle 2.0TD'!D230 -> APROBAR | G20: 0.354 | H20: 452.94 | I20: =IF('Detalle 2.0TD'!B230="","Falta PC real",IF('Detalle 2.0TD'!B230>=0.3,"OK · registrar",IF('Detalle 2.0TD'!B230>=0.2,"Revisar margen","Revisar PC/PV"))) -> OK · registrar | K20: ='Detalle 2.0TD'!AD230 -> 44.7175
A21: 8570 | B21: C02680 | C21: ALVARO DAVID OCHOA BIOSCA | D21: Naturgy | E21: ='Detalle 2.0TD'!B244 -> 0.15852433 | F21: ='Detalle 2.0TD'!D244 -> RECHAZAR | G21: 1 | H21: 2.65 | I21: =IF('Detalle 2.0TD'!B244="","Falta PC real",IF('Detalle 2.0TD'!B244>=0.3,"OK · registrar",IF('Detalle 2.0TD'!B244>=0.2,"Revisar margen","Revisar PC/PV"))) -> Revisar PC/PV | K21: ='Detalle 2.0TD'!AD244 -> -0.0008
A22: 8571 | B22: C00700 | C22: ELEEN VELTHOVEN | D22: Naturgy | E22: ='Detalle 2.0TD'!B258 -> 0.30013048 | F22: ='Detalle 2.0TD'!D258 -> APROBAR | G22: 0.1991 | H22: 1674.46 | I22: =IF('Detalle 2.0TD'!B258="","Falta PC real",IF('Detalle 2.0TD'!B258>=0.3,"OK · registrar",IF('Detalle 2.0TD'!B258>=0.2,"Revisar margen","Revisar PC/PV"))) -> OK · registrar | K22: ='Detalle 2.0TD'!AD258 -> 7.2281
A23: 8572 | B23: C01280 | C23: Mª ISABEL HEVIA TENA | D23: Naturgy | E23: ='Detalle 2.0TD'!B277 -> 0.29998179 | F23: ='Detalle 2.0TD'!D277 -> REVISAR | G23: 0.3077 | H23: 2373.43 | I23: =IF('Detalle 2.0TD'!B277="","Falta PC real",IF('Detalle 2.0TD'!B277>=0.3,"OK · registrar",IF('Detalle 2.0TD'!B277>=0.2,"Revisar margen","Revisar PC/PV"))) -> Revisar margen | K23: ='Detalle 2.0TD'!AD277 -> 10.1839
A24: 8573 | B24: C01990 | C24: GERRIT JONGEJAN | D24: Naturgy | E24: ='Detalle 2.0TD'!B296 -> 0.29999239 | F24: ='Detalle 2.0TD'!D296 -> REVISAR | G24: 0.0538 | H24: 609.46 | I24: =IF('Detalle 2.0TD'!B296="","Falta PC real",IF('Detalle 2.0TD'!B296>=0.3,"OK · registrar",IF('Detalle 2.0TD'!B296>=0.2,"Revisar margen","Revisar PC/PV"))) -> Revisar margen | K24: ='Detalle 2.0TD'!AD296 -> 2.9781
A25: 8574 | B25: C03260 | C25: MICHAL CUKAN | D25: Naturgy | E25: ='Detalle 2.0TD'!B315 -> 0.098462768 | F25: ='Detalle 2.0TD'!D315 -> RECHAZAR | G25: 1 | H25: 0.86 | I25: =IF('Detalle 2.0TD'!B315="","Falta PC real",IF('Detalle 2.0TD'!B315>=0.3,"OK · registrar",IF('Detalle 2.0TD'!B315>=0.2,"Revisar margen","Revisar PC/PV"))) -> Revisar PC/PV | K25: ='Detalle 2.0TD'!AD315 -> 0.0014
A26: 8575 | B26: C01140 | C26: DESIRÉ ANNA GUSTAAF SCHUTTER | D26: Naturgy | E26: ='Detalle 2.0TD'!B329 -> 0.30004436 | F26: ='Detalle 2.0TD'!D329 -> APROBAR | G26: 0.2556 | H26: 1316.57 | I26: =IF('Detalle 2.0TD'!B329="","Falta PC real",IF('Detalle 2.0TD'!B329>=0.3,"OK · registrar",IF('Detalle 2.0TD'!B329>=0.2,"Revisar margen","Revisar PC/PV"))) -> OK · registrar | K26: ='Detalle 2.0TD'!AD329 -> 13.6809
A27: 8579 | B27: C01350 | C27: CORDULA PETERS | D27: Naturgy | E27: ='Detalle 2.0TD'!B348 -> 0.30032926 | F27: ='Detalle 2.0TD'!D348 -> APROBAR | G27: 0.0004 | H27: 638.64 | I27: =IF('Detalle 2.0TD'!B348="","Falta PC real",IF('Detalle 2.0TD'!B348>=0.3,"OK · registrar",IF('Detalle 2.0TD'!B348>=0.2,"Revisar margen","Revisar PC/PV"))) -> OK · registrar | K27: ='Detalle 2.0TD'!AD348 -> 6.3609
A28: 8580 | B28: C00060 | C28: HV LUXO SA | D28: Naturgy | E28: ='Detalle 2.0TD'!B367 -> 0.29998609 | F28: ='Detalle 2.0TD'!D367 -> REVISAR | G28: 0.4727 | H28: 1556.34 | I28: =IF('Detalle 2.0TD'!B367="","Falta PC real",IF('Detalle 2.0TD'!B367>=0.3,"OK · registrar",IF('Detalle 2.0TD'!B367>=0.2,"Revisar margen","Revisar PC/PV"))) -> Revisar margen | K28: ='Detalle 2.0TD'!AD367 -> 8.7804
A29: 8581 | C29: MANUEL GARCÍA DEL VALLE CARLOS-ROC | D29: Naturgy | E29: ='Detalle 2.0TD'!B386 -> 0.29997434 | F29: ='Detalle 2.0TD'!D386 -> REVISAR | G29: 0.178 | H29: 3463.21 | I29: =IF('Detalle 2.0TD'!B386="","Falta PC real",IF('Detalle 2.0TD'!B386>=0.3,"OK · registrar",IF('Detalle 2.0TD'!B386>=0.2,"Revisar margen","Revisar PC/PV"))) -> Revisar margen | K29: ='Detalle 2.0TD'!AD386 -> 27.0447
A30: 8584 | B30: C00040 | C30: Mª ROSARIO ORTOLÁ FERRER | D30: Naturgy | E30: ='Detalle 2.0TD'!B400 -> 0.30001544 | F30: ='Detalle 2.0TD'!D400 -> APROBAR | G30: 0.3577 | H30: 10840.8 | I30: =IF('Detalle 2.0TD'!B400="","Falta PC real",IF('Detalle 2.0TD'!B400>=0.3,"OK · registrar",IF('Detalle 2.0TD'!B400>=0.2,"Revisar margen","Revisar PC/PV"))) -> OK · registrar | K30: ='Detalle 2.0TD'!AD400 -> 7.3982
A31: 8585 | B31: C00050 | C31: HELADOS ESPI | D31: Naturgy | E31: ='Detalle 2.0TD'!B419 -> 0.29996745 | F31: ='Detalle 2.0TD'!D419 -> REVISAR | G31: 0.301 | H31: 5330.72 | I31: =IF('Detalle 2.0TD'!B419="","Falta PC real",IF('Detalle 2.0TD'!B419>=0.3,"OK · registrar",IF('Detalle 2.0TD'!B419>=0.2,"Revisar margen","Revisar PC/PV"))) -> Revisar margen | K31: ='Detalle 2.0TD'!AD419 -> 19.2773
A32: 8586 | B32: C00060 | C32: HV LUXO SA | D32: Naturgy | E32: ='Detalle 2.0TD'!B438 -> 0.29998609 | F32: ='Detalle 2.0TD'!D438 -> REVISAR | G32: 0.4727 | H32: 1556.34 | I32: =IF('Detalle 2.0TD'!B438="","Falta PC real",IF('Detalle 2.0TD'!B438>=0.3,"OK · registrar",IF('Detalle 2.0TD'!B438>=0.2,"Revisar margen","Revisar PC/PV"))) -> Revisar margen | K32: ='Detalle 2.0TD'!AD438 -> 8.7804
A33: 8588 | B33: C00100 | C33: CRISTINA MARÍA FALCÓN ESCALONA | D33: Naturgy | E33: ='Detalle 2.0TD'!B457 -> 0.37156635 | F33: ='Detalle 2.0TD'!D457 -> APROBAR | G33: 0.4676 | H33: 1874.26 | I33: =IF('Detalle 2.0TD'!B457="","Falta PC real",IF('Detalle 2.0TD'!B457>=0.3,"OK · registrar",IF('Detalle 2.0TD'!B457>=0.2,"Revisar margen","Revisar PC/PV"))) -> OK · registrar | K33: ='Detalle 2.0TD'!AD457 -> 0.0069
A34: 8589 | B34: C00120 | C34: STEPHEN RICHARD ROBINSON | D34: Naturgy | E34: ='Detalle 2.0TD'!B476 -> 0.32105091 | F34: ='Detalle 2.0TD'!D476 -> APROBAR | G34: 0.3197 | H34: 3583.48 | I34: =IF('Detalle 2.0TD'!B476="","Falta PC real",IF('Detalle 2.0TD'!B476>=0.3,"OK · registrar",IF('Detalle 2.0TD'!B476>=0.2,"Revisar margen","Revisar PC/PV"))) -> OK · registrar | K34: ='Detalle 2.0TD'!AD476 -> -0.0005
A35: 8590 | B35: C00130 | C35: BIO JARDINSOSTENIBLE, S.L.U. | D35: Naturgy | E35: ='Detalle 2.0TD'!B495 -> 0.30004484 | F35: ='Detalle 2.0TD'!D495 -> APROBAR | G35: 0.4296 | H35: 3448.6 | I35: =IF('Detalle 2.0TD'!B495="","Falta PC real",IF('Detalle 2.0TD'!B495>=0.3,"OK · registrar",IF('Detalle 2.0TD'!B495>=0.2,"Revisar margen","Revisar PC/PV"))) -> OK · registrar | K35: ='Detalle 2.0TD'!AD495 -> 7.8379
A36: 8593 | B36: C00270 | C36: CLAUDE JOSÉ GOFFINET | D36: Naturgy | E36: ='Detalle 2.0TD'!B514 -> 0.29997655 | F36: ='Detalle 2.0TD'!D514 -> REVISAR | G36: 0.46 | H36: 4468.12 | I36: =IF('Detalle 2.0TD'!B514="","Falta PC real",IF('Detalle 2.0TD'!B514>=0.3,"OK · registrar",IF('Detalle 2.0TD'!B514>=0.2,"Revisar margen","Revisar PC/PV"))) -> Revisar margen | K36: ='Detalle 2.0TD'!AD514 -> 16.9141
A37: 8594 | B37: C00310 | C37: MICHAEL BALMER | D37: Naturgy | E37: ='Detalle 2.0TD'!B533 -> 0.30009093 | F37: ='Detalle 2.0TD'!D533 -> APROBAR | G37: 0.5097 | H37: 1087.08 | I37: =IF('Detalle 2.0TD'!B533="","Falta PC real",IF('Detalle 2.0TD'!B533>=0.3,"OK · registrar",IF('Detalle 2.0TD'!B533>=0.2,"Revisar margen","Revisar PC/PV"))) -> OK · registrar | K37: ='Detalle 2.0TD'!AD533 -> 17.0578
A38: 8597 | B38: C00410 | C38: VALENTINA BARCA | D38: Naturgy | E38: ='Detalle 2.0TD'!B552 -> 0.30004773 | F38: ='Detalle 2.0TD'!D552 -> APROBAR | G38: 0.3904 | H38: 3173.99 | I38: =IF('Detalle 2.0TD'!B552="","Falta PC real",IF('Detalle 2.0TD'!B552>=0.3,"OK · registrar",IF('Detalle 2.0TD'!B552>=0.2,"Revisar margen","Revisar PC/PV"))) -> OK · registrar | K38: ='Detalle 2.0TD'!AD552 -> 23.2819
A39: 8599 | B39: C00540 | C39: PEDRO CAÑADAS FERNANDEZ | D39: Naturgy | E39: ='Detalle 2.0TD'!B571 -> 0.30028533 | F39: ='Detalle 2.0TD'!D571 -> APROBAR | G39: 0.2884 | H39: 910.46 | I39: =IF('Detalle 2.0TD'!B571="","Falta PC real",IF('Detalle 2.0TD'!B571>=0.3,"OK · registrar",IF('Detalle 2.0TD'!B571>=0.2,"Revisar margen","Revisar PC/PV"))) -> OK · registrar | K39: ='Detalle 2.0TD'!AD571 -> 6.3639
A40: 8600 | B40: C00670 | C40: CARLOS A. GAVILANES PAUCAR | D40: Naturgy | E40: ='Detalle 2.0TD'!B590 -> 0.30002542 | F40: ='Detalle 2.0TD'!D590 -> APROBAR | G40: 0.4352 | H40: 5027.47 | I40: =IF('Detalle 2.0TD'!B590="","Falta PC real",IF('Detalle 2.0TD'!B590>=0.3,"OK · registrar",IF('Detalle 2.0TD'!B590>=0.2,"Revisar margen","Revisar PC/PV"))) -> OK · registrar | K40: ='Detalle 2.0TD'!AD590 -> 29.9134
...

Sheet Detalle 2.0TD
A1: VALIDACIÓN FACTURAS 2.0TD · abril 2026 · Transactiva 2000 S.L. (Días = solo potencia/alquiler/bono · PC ámbar editable · margen objetivo editable por factura)
A3: Factura 8550 · C02150 · FUNDACIÓN FSU PROGRAMAS INTERNACIONALES | H3: ES0021000020111640FT · Naturgy | L3: 46113 | M3: a | N3: 46142 | R3: HISTÓRICO DEL CUPS · HOJA TTVA LUZ
A4: Concepto | B4: PENDIENTE (sin registrar) | H4: MES ANTERIOR · Fact.6304 | L4: AÑO ANTERIOR · Fact.4583 | R4: Cobrado total: 2.436 €
B5: Cant | C5: Días | D5: PC real | E5: PV | F5: Importe | H5: Cant | I5: PV | J5: Importe | L5: Cant | M5: PV | N5: Importe | R5: Pagado total: 1.753 €
A6: P1 Potencia | B6: 10.392 | C6: =$N$3-$L$3+1 -> 30 | D6: 3.68919 | E6: 4.82 | F6: =ROUND(B6*E6,2) -> 50.09 | H6: 10.392 | I6: 4.82 | J6: =ROUND(H6*I6,2) -> 50.09 | L6: 10.392 | M6: 4.82 | N6: =ROUND(L6*M6,2) -> 50.09 | R6: DIF: 682 € · Margen hist.: 28.0%
A7: P2 Potencia | B7: 10.392 | C7: =$N$3-$L$3+1 -> 30 | D7: 1.31928 | E7: 2.37 | F7: =ROUND(B7*E7,2) -> 24.63 | H7: 10.392 | I7: 2.37 | J7: =ROUND(H7*I7,2) -> 24.63 | L7: 10.392 | M7: 2.37 | N7: =ROUND(L7*M7,2) -> 24.63 | R7: Mejor mes: 2024-09 · 526 € · margen 197%
A8: P1 Energía | B8: =IF($P$8<>"",ROUND(AA8*(($AB$8/(1-$P$8))-74.7185)/113.0879,2),IF('Resumen 2.0TD'!$D$3="OPTIMIZAR",ROUND(MAX(AA8,MIN(AA8*(($AB$8/(1-'Resumen 2.0TD'!$F$3))-74.7185)/113.0879,AA8*(439.4393)/113.0879)),3),AA8)) -> 195.263 | D8: 0.111171 | E8: 0.17 | F8: =ROUND(B8*E8,2) -> 33.19 | H8: 477.269 | I8: 0.175 | J8: =ROUND(H8*I8,2) -> 83.52 | L8: 95.263 | M8: 0.175 | N8: =ROUND(L8*M8,2) -> 16.67 | O8: Margen objetivo (edita % aquí) ▶ | R8: Peor mes: 2024-08 · 66 € · margen 66% | AA8: 195.263 | AB8: =B6*D6+B7*D7+AA8*D8+AA9*D9+AA10*D10 -> 126.00153
A9: P2 Energía | B9: =IF($P$8<>"",ROUND(AA9*(($AB$8/(1-$P$8))-74.7185)/113.0879,2),IF('Resumen 2.0TD'!$D$3="OPTIMIZAR",ROUND(MAX(AA9,MIN(AA9*(($AB$8/(1-'Resumen 2.0TD'!$F$3))-74.7185)/113.0879,AA9*(439.4393)/113.0879)),3),AA9)) -> 199.672 | D9: 0.111171 | E9: 0.17 | F9: =ROUND(B9*E9,2) -> 33.94 | H9: 460.686 | I9: 0.175 | J9: =ROUND(H9*I9,2) -> 80.62 | L9: 99.672 | M9: 0.175 | N9: =ROUND(L9*M9,2) -> 17.44 | O9: Cant. P1/P2/P3 energía suben | R9: Importe mensual cobrado (€) · 24 meses ▾ | AA9: 199.672
A10: P3 Energía | B10: =IF($P$8<>"",ROUND(AA10*(($AB$8/(1-$P$8))-74.7185)/113.0879,2),IF('Resumen 2.0TD'!$D$3="OPTIMIZAR",ROUND(MAX(AA10,MIN(AA10*(($AB$8/(1-'Resumen 2.0TD'!$F$3))-74.7185)/113.0879,AA10*(439.4393)/113.0879)),3),AA10)) -> 270.288 | D10: 0.111171 | E10: 0.17 | F10: =ROUND(B10*E10,2) -> 45.95 | H10: 525.938 | I10: 0.175 | J10: =ROUND(H10*I10,2) -> 92.04 | L10: 170.288 | M10: 0.175 | N10: =ROUND(L10*M10,2) -> 29.8 | O10: en proporción para ese margen | AA10: 270.288
A11: Alquiler contador | B11: 1 | C11: =$N$3-$L$3+1 -> 30 | D11: 1.3414 | E11: 1 | F11: =ROUND(B11*E11,2) -> 1 | H11: 1 | I11: 1 | J11: =ROUND(H11*I11,2) -> 1 | L11: 1 | M11: 1 | N11: =ROUND(L11*M11,2) -> 1
A12: Bono social | B12: 30 | C12: =$N$3-$L$3+1 -> 30 | D12: 0.5736 | E12: 0.01274 | F12: =ROUND(B12*E12,2) -> 0.38 | H12: 30 | I12: 0.01274 | J12: =ROUND(H12*I12,2) -> 0.38 | L12: 30 | M12: 0.00685 | N12: =ROUND(L12*M12,2) -> 0.21
A13: Tasa eléctrica | B13: 10.03 | D13: 0.27312 | E13: 1 | F13: =ROUND(B13*E13,2) -> 10.03 | H13: 17.16 | I13: 1 | J13: =ROUND(H13*I13,2) -> 17.16 | L13: 7.09 | M13: 1 | N13: =ROUND(L13*M13,2) -> 7.09
A14: TOTAL c/IVA | F14: =ROUND((SUM(F6:F13)-F13)*1.1+F13,2) -> 218.13 | J14: =ROUND(SUM(J6:J13),2) -> 349.44 | N14: =ROUND(SUM(N6:N13),2) -> 146.93
A15: MARGEN sin registrar | B15: =IF((F10+F9+F8+F6+F7)=0,"",((F10+F9+F8+F6+F7)-$AB$8)/(F10+F9+F8+F6+F7)) -> 0.32906535 | D15: =IF(B15="","SIN PC",IF(B15>=0.3,"APROBAR",IF(B15>=0.2,"REVISAR","RECHAZAR"))) -> APROBAR | AD15: =SUM(F8:F10)-113.0879 -> -0.0079
A17: Factura 8551 · C02140 · FUNDACIÓN FSU PROGRAMAS INTERNACIONALES | H17: ES0021000008997145KW · Naturgy | L17: 46113 | M17: a | N17: 46142 | R17: HISTÓRICO DEL CUPS · HOJA TTVA LUZ
A18: Concepto | B18: PENDIENTE (sin registrar) | H18: MES ANTERIOR · Fact.6308 | L18: AÑO ANTERIOR · Fact.4584 | R18: Cobrado total: 2.120 €
B19: Cant | C19: Días | D19: PC real | E19: PV | F19: Importe | H19: Cant | I19: PV | J19: Importe | L19: Cant | M19: PV | N19: Importe | R19: Pagado total: 1.617 €
A20: P1 Potencia | B20: 10.392 | C20: =$N$17-$L$17+1 -> 30 | D20: 3.68919 | E20: 4.82 | F20: =ROUND(B20*E20,2) -> 50.09 | H20: 10.392 | I20: 4.82 | J20: =ROUND(H20*I20,2) -> 50.09 | L20: 10.392 | M20: 4.82 | N20: =ROUND(L20*M20,2) -> 50.09 | R20: DIF: 503 € · Margen hist.: 23.7%
A21: P2 Potencia | B21: 10.392 | C21: =$N$17-$L$17+1 -> 30 | D21: 1.31928 | E21: 2.37 | F21: =ROUND(B21*E21,2) -> 24.63 | H21: 10.392 | I21: 2.37 | J21: =ROUND(H21*I21,2) -> 24.63 | L21: 10.392 | M21: 2.37 | N21: =ROUND(L21*M21,2) -> 24.63 | R21: Mejor mes: 2024-07 · 345 € · margen 79%
A22: P1 Energía | B22: =IF($P$22<>"",ROUND(AA22*(($AB$22/(1-$P$22))-74.7185)/100.7259,2),IF('Resumen 2.0TD'!$D$3="OPTIMIZAR",ROUND(MAX(AA22,MIN(AA22*(($AB$22/(1-'Resumen 2.0TD'!$F$3))-74.7185)/100.7259,AA22*(259.0793)/100.7259)),3),AA22)) -> 177.5 | D22: 0.111171 | E22: 0.17 | F22: =ROUND(B22*E22,2) -> 30.18 | H22: 309.614 | I22: 0.175 | J22: =ROUND(H22*I22,2) -> 54.18 | L22: 77.5 | M22: 0.175 | N22: =ROUND(L22*M22,2) -> 13.56 | O22: Margen objetivo (edita % aquí) ▶ | R22: Peor mes: 2024-08 · 84 € · margen 37% | AA22: 177.5 | AB22: =B20*D20+B21*D21+AA22*D22+AA23*D23+AA24*D24 -> 117.91739
A23: P2 Energía | B23: =IF($P$22<>"",ROUND(AA23*(($AB$22/(1-$P$22))-74.7185)/100.7259,2),IF('Resumen 2.0TD'!$D$3="OPTIMIZAR",ROUND(MAX(AA23,MIN(AA23*(($AB$22/(1-'Resumen 2.0TD'!$F$3))-74.7185)/100.7259,AA23*(259.0793)/100.7259)),3),AA23)) -> 168.86 | D23: 0.111171 | E23: 0.17 | F23: =ROUND(B23*E23,2) -> 28.71 | H23: 186.461 | I23: 0.175 | J23: =ROUND(H23*I23,2) -> 32.63 | L23: 68.86 | M23: 0.175 | N23: =ROUND(L23*M23,2) -> 12.05 | O23: Cant. P1/P2/P3 energía suben | R23: Importe mensual cobrado (€) · 24 meses ▾ | AA23: 168.86
A24: P3 Energía | B24: =IF($P$22<>"",ROUND(AA24*(($AB$22/(1-$P$22))-74.7185)/100.7259,2),IF('Resumen 2.0TD'!$D$3="OPTIMIZAR",ROUND(MAX(AA24,MIN(AA24*(($AB$22/(1-'Resumen 2.0TD'!$F$3))-74.7185)/100.7259,AA24*(259.0793)/100.7259)),3),AA24)) -> 246.145 | D24: 0.111171 | E24: 0.17 | F24: =ROUND(B24*E24,2) -> 41.84 | H24: 355.272 | I24: 0.175 | J24: =ROUND(H24*I24,2) -> 62.17 | L24: 146.145 | M24: 0.175 | N24: =ROUND(L24*M24,2) -> 25.58 | O24: en proporción para ese margen | AA24: 246.145
A25: Alquiler contador | B25: 1 | C25: =$N$17-$L$17+1 -> 30 | D25: 1.3414 | E25: 1 | F25: =ROUND(B25*E25,2) -> 1 | H25: 1 | I25: 1 | J25: =ROUND(H25*I25,2) -> 1 | L25: 1 | M25: 1 | N25: =ROUND(L25*M25,2) -> 1
A26: Bono social | B26: 30 | C26: =$N$17-$L$17+1 -> 30 | D26: 0.5736 | E26: 0.01274 | F26: =ROUND(B26*E26,2) -> 0.38 | H26: 30 | I26: 0.01274 | J26: =ROUND(H26*I26,2) -> 0.38 | L26: 30 | M26: 0.00685 | N26: =ROUND(L26*M26,2) -> 0.21
A27: Tasa eléctrica | B27: 9.37 | D27: 0.27312 | E27: 1 | F27: =ROUND(B27*E27,2) -> 9.37 | H27: 12.1 | I27: 1 | J27: =ROUND(H27*I27,2) -> 12.1 | L27: 6.44 | M27: 1 | N27: =ROUND(L27*M27,2) -> 6.44
A28: TOTAL c/IVA | F28: =ROUND((SUM(F20:F27)-F27)*1.1+F27,2) -> 203.88 | J28: =ROUND(SUM(J20:J27),2) -> 237.18 | N28: =ROUND(SUM(N20:N27),2) -> 133.56
A29: MARGEN sin registrar | B29: =IF((F24+F23+F22+F20+F21)=0,"",((F24+F23+F22+F20+F21)-$AB$22)/(F24+F23+F22+F20+F21)) -> 0.32791454 | D29: =IF(B29="","SIN PC",IF(B29>=0.3,"APROBAR",IF(B29>=0.2,"REVISAR","RECHAZAR"))) -> APROBAR | AD29: =SUM(F22:F24)-100.7259 -> 0.0041
A31: Factura 8552 · C02130 · FUNDACIÓN FSU PROGRAMAS INTERNACIONALES | H31: ES0021000012268833JD · Naturgy | L31: 46113 | M31: a | N31: 46142 | R31: HISTÓRICO DEL CUPS · HOJA TTVA LUZ
A32: Concepto | B32: PENDIENTE (sin registrar) | H32: MES ANTERIOR · Fact.6311 | L32: AÑO ANTERIOR · Fact.4585 | R32: Cobrado total: 3.194 €
B33: Cant | C33: Días | D33: PC real | E33: PV | F33: Importe | H33: Cant | I33: PV | J33: Importe | L33: Cant | M33: PV | N33: Importe | R33: Pagado total: 2.235 €
A34: P1 Potencia | B34: 6.928 | C34: =$N$31-$L$31+1 -> 30 | D34: 3.68919 | E34: 4.82 | F34: =ROUND(B34*E34,2) -> 33.39 | H34: 6.928 | I34: 4.82 | J34: =ROUND(H34*I34,2) -> 33.39 | L34: 6.928 | M34: 4.82 | N34: =ROUND(L34*M34,2) -> 33.39 | R34: DIF: 960 € · Margen hist.: 30.0%
A35: P2 Potencia | B35: 6.928 | C35: =$N$31-$L$31+1 -> 30 | D35: 1.31928 | E35: 2.37 | F35: =ROUND(B35*E35,2) -> 16.42 | H35: 6.928 | I35: 2.37 | J35: =ROUND(H35*I35,2) -> 16.42 | L35: 6.928 | M35: 2.37 | N35: =ROUND(L35*M35,2) -> 16.42 | R35: Mejor mes: 2024-07 · 613 € · margen 71%
A36: P1 Energía | B36: =IF($P$36<>"",ROUND(AA36*(($AB$36/(1-$P$36))-49.8123)/207.1457,2),IF('Resumen 2.0TD'!$D$3="OPTIMIZAR",ROUND(MAX(AA36,MIN(AA36*(($AB$36/(1-'Resumen 2.0TD'!$F$3))-49.8123)/207.1457,AA36*(548.5955)/207.1457)),3),AA36)) -> 301.884 | D36: 0.111171 | E36: 0.17 | F36: =ROUND(B36*E36,2) -> 51.32 | H36: 250.417 | I36: 0.175 | J36: =ROUND(H36*I36,2) -> 43.82 | L36: 201.884 | M36: 0.175 | N36: =ROUND(L36*M36,2) -> 35.33 | O36: Margen objetivo (edita % aquí) ▶ | R36: Peor mes: 2024-08 · 129 € · margen 25% | AA36: 301.884 | AB36: =B34*D34+B35*D35+AA36*D36+AA37*D37+AA38*D38 -> 170.16099
A37: P2 Energía | B37: =IF($P$36<>"",ROUND(AA37*(($AB$36/(1-$P$36))-49.8123)/207.1457,2),IF('Resumen 2.0TD'!$D$3="OPTIMIZAR",ROUND(MAX(AA37,MIN(AA37*(($AB$36/(1-'Resumen 2.0TD'!$F$3))-49.8123)/207.1457,AA37*(548.5955)/207.1457)),3),AA37)) -> 374.313 | D37: 0.111171 | E37: 0.17 | F37: =ROUND(B37*E37,2) -> 63.63 | H37: 234.006 | I37: 0.175 | J37: =ROUND(H37*I37,2) -> 40.95 | L37: 174.313 | M37: 0.175 | N37: =ROUND(L37*M37,2) -> 30.5 | O37: Cant. P1/P2/P3 energía suben | R37: Importe mensual cobrado (€) · 24 meses ▾ | AA37: 374.313
A38: P3 Energía | B38: =IF($P$36<>"",ROUND(AA38*(($AB$36/(1-$P$36))-49.8123)/207.1457,2),IF('Resumen 2.0TD'!$D$3="OPTIMIZAR",ROUND(MAX(AA38,MIN(AA38*(($AB$36/(1-'Resumen 2.0TD'!$F$3))-49.8123)/207.1457,AA38*(548.5955)/207.1457)),3),AA38)) -> 542.307 | D38: 0.111171 | E38: 0.17 | F38: =ROUND(B38*E38,2) -> 92.19 | H38: 376.925 | I38: 0.175 | J38: =ROUND(H38*I38,2) -> 65.96 | L38: 342.307 | M38: 0.175 | N38: =ROUND(L38*M38,2) -> 59.9 | O38: en proporción para ese margen | AA38: 542.307
A39: Alquiler contador | B39: 1 | C39: =$N$31-$L$31+1 -> 30 | D39: 1.3414 | E39: 1 | F39: =ROUND(B39*E39,2) -> 1 | H39: 1 | I39: 1 | J39: =ROUND(H39*I39,2) -> 1 | L39: 1 | M39: 1 | N39: =ROUND(L39*M39,2) -> 1
A40: Bono social | B40: 30 | C40: =$N$31-$L$31+1 -> 30 | D40: 0.5736 | E40: 0.01274 | F40: =ROUND(B40*E40,2) -> 0.38 | H40: 30 | I40: 0.01274 | J40: =ROUND(H40*I40,2) -> 0.38 | L40: 30 | M40: 0.00685 | N40: =ROUND(L40*M40,2) -> 0.21
A41: Tasa eléctrica | B41: 13.65 | D41: 0.27312 | E41: 1 | F41: =ROUND(B41*E41,2) -> 13.65 | H41: 12.86 | I41: 1 | J41: =ROUND(H41*I41,2) -> 12.86 | L41: 8.83 | M41: 1 | N41: =ROUND(L41*M41,2) -> 8.83
A42: TOTAL c/IVA | F42: =ROUND((SUM(F34:F41)-F41)*1.1+F41,2) -> 297.81 | J42: =ROUND(SUM(J34:J41),2) -> 214.78 | N42: =ROUND(SUM(N34:N41),2) -> 185.58
A43: MARGEN sin registrar | B43: =IF((F38+F37+F36+F34+F35)=0,"",((F38+F37+F36+F34+F35)-$AB$36)/(F38+F37+F36+F34+F35)) -> 0.33776615 | D43: =IF(B43="","SIN PC",IF(B43>=0.3,"APROBAR",IF(B43>=0.2,"REVISAR","RECHAZAR"))) -> APROBAR | AD43: =SUM(F36:F38)-207.1457 -> -0.0057
...

Sheet _series_3
A1: nf | B1: 2024-07 | C1: 2024-08 | D1: 2024-09 | E1: 2024-10 | F1: 2024-11 | G1: 2024-12 | H1: 2025-01 | I1: 2025-02 | J1: 2025-03 | K1: 2025-04 | L1: 2025-05 | M1: 2025-06 | N1: 2025-07 | O1: 2025-08 | P1: 2025-09 | Q1: 2025-10 | R1: 2025-11 | S1: 2025-12 | T1: 2026-01 | U1: 2026-02 | V1: 2026-03 | W1: 2026-04 | X1: 2026-05 | Y1: 2026-06
A2: 8544 | B2: 1823.2 | C2: 2200.79 | D2: 1506.86 | E2: 1294.73 | F2: 701.24 | G2: 2057.58 | H2: 704.65 | I2: 1131.33 | J2: 1195.22 | K2: 1397.39 | L2: 1489.78 | M2: 1604.92 | N2: 2264.68 | O2: 2392.22 | P2: 1906.5 | Q2: 1541.7 | R2: 1553.06 | S2: 1623.98 | T2: 1669.87 | U2: 1287.26 | V2: 1560.23 | W2: 1696.52 | X2: 1398.99 | Y2: 1699.39
A3: 8545 | B3: 2278.23 | C3: 2606.49 | D3: 1372.78 | E3: 1218.04 | F3: 852.42 | G3: 892.96 | H3: 526.46 | I3: 703.02 | J3: 973.88 | K3: 1071.5 | L3: 1198.45 | M3: 1352.91 | N3: 2137.78 | O3: 2576.37 | P3: 1966.13 | Q3: 1508.21 | R3: 982.22 | S3: 980.76 | T3: 639.12 | U3: 1081.39 | V3: 1166.31 | W3: 1408.31 | X3: 1317.52 | Y3: 0
A4: 8546 | B4: 0 | C4: 0 | D4: 0 | E4: 0 | F4: 0 | G4: 0 | H4: 0 | I4: 0 | J4: 0 | K4: 0 | L4: 0 | M4: 0 | N4: 0 | O4: 0 | P4: 0 | Q4: 0 | R4: 0 | S4: 0 | T4: 0 | U4: 1625.21 | V4: 3262.26 | W4: 3637.92 | X4: 3747.07 | Y4: 0
A5: 8547 | B5: 4696.57 | C5: 5119.32 | D5: 3940.09 | E5: 4434.05 | F5: 4230.84 | G5: 4056.83 | H5: 3691.35 | I5: 4434.05 | J5: 4606.23 | K5: 3691.35 | L5: 3472.32 | M5: 3278.22 | N5: 4267.48 | O5: 4424.02 | P5: 3939.03 | Q5: 3404.76 | R5: 3733.87 | S5: 3769.58 | T5: 2917.21 | U5: 3522.69 | V5: 3557.98 | W5: 3087.33 | X5: 3133.52 | Y5: 3743.04
A6: 8564 | B6: 643.79 | C6: 476.53 | D6: 592.3 | E6: 631.06 | F6: 457.49 | G6: 578.16 | H6: 596.33 | I6: 602.79 | J6: 791.23 | K6: 624.49 | L6: 601.33 | M6: 711.31 | N6: 738.16 | O6: 605.43 | P6: 803.47 | Q6: 816.36 | R6: 572.69 | S6: 690.5 | T6: 712.22 | U6: 695.09 | V6: 791.23 | W6: 741.17 | X6: 782.58 | Y6: 755.25
A7: 8565 | B7: 632.44 | C7: 592.69 | D7: 610.04 | E7: 632.66 | F7: 637.18 | G7: 207.37 | H7: 706.19 | I7: 645.52 | J7: 899.33 | K7: 591.1 | L7: 643.89 | M7: 696.92 | N7: 731.73 | O7: 688.65 | P7: 794.97 | Q7: 824.16 | R7: 684.8 | S7: 331.28 | T7: 819.21 | U7: 753.83 | V7: 1018.62 | W7: 685.61 | X7: 741.79 | Y7: 789.76
A8: 8566 | B8: 524.5 | C8: 166.78 | D8: 444.46 | E8: 345.59 | F8: 0 | G8: 233.91 | H8: 294.11 | I8: 270.48 | J8: 383.23 | K8: 290.33 | L8: 336.88 | M8: 502.61 | N8: 634.9 | O8: 239.55 | P8: 628.5 | Q8: 440.92 | R8: 411.49 | S8: 407.39 | T8: 420.96 | U8: 391.83 | V8: 427.24 | W8: 354.48 | X8: 412.63 | Y8: 593.22
A9: 8567 | B9: 4475.16 | C9: 4612.54 | D9: 3701.38 | E9: 4561.47 | F9: 3334.09 | G9: 3216.6 | H9: 2924.41 | I9: 2743.54 | J9: 3702.5 | K9: 3817.43 | L9: 3300.04 | M9: 2798.1 | N9: 3784.48 | O9: 3716.14 | P9: 3334.45 | Q9: 3275.16 | R9: 3190.07 | S9: 2956.24 | T9: 2736.06 | U9: 2890.35 | V9: 3365.79 | W9: 2721.04 | X9: 2640.22 | Y9: 3260.09
A10: 8578 | B10: 151.82 | C10: 199.06 | D10: 183.84 | E10: 178.12 | F10: 184.03 | G10: 163.02 | H10: 136.55 | I10: 104.41 | J10: 98.7 | K10: 40.05 | L10: 67.35 | M10: 65.71 | N10: 361.06 | O10: 201.13 | P10: 85.6 | Q10: 63.93 | R10: 60.72 | S10: 51.57 | T10: 43.55 | U10: 40.37 | V10: 82.31 | W10: 38.53 | X10: 39.81 | Y10: 0
A11: 8615 | B11: 1167.19 | C11: 1131.86 | D11: 610.86 | E11: 553.94 | F11: 544.65 | G11: 727.09 | H11: 952.35 | I11: 581.27 | J11: 746.2 | K11: 543.77 | L11: 442.06 | M11: 643.81 | N11: 881.89 | O11: 963.15 | P11: 800.92 | Q11: 588.39 | R11: 478.95 | S11: 812.61 | T11: 783.67 | U11: 595.95 | V11: 634.87 | W11: 433.2 | X11: 544.11 | Y11: 0
A12: 8629 | B12: 128.85 | C12: 119.74 | D12: 120.37 | E12: 126 | F12: 121.75 | G12: 129.12 | H12: 118.2 | I12: 116.61 | J12: 118.21 | K12: 118.11 | L12: 120.31 | M12: 110.46 | N12: 126.3 | O12: 120.84 | P12: 118.41 | Q12: 110.34 | R12: 143.28 | S12: 123.63 | T12: 117.54 | U12: 119.84 | V12: 122.01 | W12: 115.84 | X12: 0 | Y12: 0
A13: 8635 | B13: 1506.8 | C13: 1792.99 | D13: 833.07 | E13: 766.01 | F13: 194.02 | G13: 665.19 | H13: 676.36 | I13: 603.95 | J13: 730.96 | K13: 678.97 | L13: 774.09 | M13: 774.72 | N13: 1594.97 | O13: 1863.52 | P13: 1379.87 | Q13: 902.28 | R13: 243.48 | S13: 790.46 | T13: 762.17 | U13: 615.97 | V13: 542.6 | W13: 641.56 | X13: 747.69 | Y13: 0
... A28: 8738 | B28: 0 | C28: 0 | D28: 0 | E28: 0 | F28: 1197.18 | G28: 1865.97 | H28: 1723.16 | I28: 1570.31 | J28: 1432.73 | K28: 1817.32 | L28: 1955.83 | M28: 2235.47 | N28: 2825.24 | O28: 3443.22 | P28: 3178.08 | Q28: 2134.16 | R28: 1883.16 | S28: 1916.12 | T28: 1372.39 | U28: 2844.42 | V28: 2594.23 | W28: 2436.29 | X28: 2434.85 | Y28: 0

Sheet _series_2
A1: nf | B1: 2024-07 | C1: 2024-08 | D1: 2024-09 | E1: 2024-10 | F1: 2024-11 | G1: 2024-12 | H1: 2025-01 | I1: 2025-02 | J1: 2025-03 | K1: 2025-04 | L1: 2025-05 | M1: 2025-06 | N1: 2025-07 | O1: 2025-08 | P1: 2025-09 | Q1: 2025-10 | R1: 2025-11 | S1: 2025-12 | T1: 2026-01 | U1: 2026-02 | V1: 2026-03 | W1: 2026-04 | X1: 2026-05 | Y1: 2026-06
A2: 8550 | B2: 0 | C2: 0 | D2: 0 | E2: 0 | F2: 0 | G2: 67.85 | H2: 291.23 | I2: 212.91 | J2: 183.41 | K2: 146.93 | L2: 240.12 | M2: 360.36 | N2: 489.63 | O2: 103.62 | P2: 664.91 | Q2: 334.22 | R2: 254.97 | S2: 121.53 | T2: 392.65 | U2: 287.51 | V2: 349.44 | W2: 199.21 | X2: 273.87 | Y2: 430.03
A3: 8551 | B3: 0 | C3: 0 | D3: 0 | E3: 0 | F3: 0 | G3: 122.79 | H3: 257.6 | I3: 149.89 | J3: 179.34 | K3: 133.56 | L3: 217.18 | M3: 255.1 | N3: 355.24 | O3: 132.59 | P3: 333.79 | Q3: 306.02 | R3: 209.78 | S3: 189.38 | T3: 339.72 | U3: 188.55 | V3: 237.18 | W3: 186.2 | X3: 276 | Y3: 343.77
A4: 8552 | B4: 0 | C4: 0 | D4: 0 | E4: 0 | F4: 0 | G4: 240.78 | H4: 270.33 | I4: 122.02 | J4: 156.75 | K4: 185.58 | L4: 220.94 | M4: 589.63 | N4: 626.48 | O4: 164.89 | P4: 386.56 | Q4: 382.69 | R4: 261.9 | S4: 330.96 | T4: 371.28 | U4: 169.53 | V4: 214.78 | W4: 271.98 | X4: 271.88 | Y4: 692.94
A5: 8553 | B5: 0 | C5: 0 | D5: 0 | E5: 0 | F5: 0 | G5: 143.34 | H5: 255.18 | I5: 122.89 | J5: 228.55 | K5: 175.12 | L5: 270.51 | M5: 388.07 | N5: 574.82 | O5: 154.53 | P5: 359.42 | Q5: 352.4 | R5: 177.06 | S5: 261.13 | T5: 337.12 | U5: 149.42 | V5: 232.63 | W5: 279.54 | X5: 333.42 | Y5: 462.7
A6: 8554 | B6: 0 | C6: 0 | D6: 0 | E6: 0 | F6: 0 | G6: 181.06 | H6: 235.48 | I6: 115.38 | J6: 164.69 | K6: 208.48 | L6: 620.36 | M6: 776.69 | N6: 910.68 | O6: 276.4 | P6: 777.08 | Q6: 555.31 | R6: 267.98 | S6: 240.42 | T6: 316.78 | U6: 165.48 | V6: 218.11 | W6: 311.55 | X6: 651.31 | Y6: 839.16
A7: 8555 | B7: 0 | C7: 0 | D7: 0 | E7: 0 | F7: 0 | G7: 98.79 | H7: 169.59 | I7: 113.34 | J7: 142.42 | K7: 111.81 | L7: 150.31 | M7: 280.5 | N7: 374.5 | O7: 130.26 | P7: 333.66 | Q7: 240.63 | R7: 117.47 | S7: 166.39 | T7: 229.98 | U7: 152.99 | V7: 196.1 | W7: 164.11 | X7: 189.25 | Y7: 351.03
A8: 8556 | B8: 0 | C8: 0 | D8: 0 | E8: 0 | F8: 0 | G8: 170.28 | H8: 258.52 | I8: 181.42 | J8: 255.74 | K8: 242.83 | L8: 303.68 | M8: 367.91 | N8: 611.02 | O8: 163.33 | P8: 392.33 | Q8: 376.51 | R8: 126.21 | S8: 230.73 | T8: 340.4 | U8: 259.71 | V8: 311.91 | W8: 314.39 | X8: 371.77 | Y8: 505.17
A9: 8557 | B9: 0 | C9: 0 | D9: 0 | E9: 0 | F9: 0 | G9: 193.05 | H9: 309.11 | I9: 197.99 | J9: 256.8 | K9: 114.01 | L9: 245.88 | M9: 405.6 | N9: 510.83 | O9: 181.08 | P9: 334.97 | Q9: 263.34 | R9: 146.93 | S9: 251.21 | T9: 411.51 | U9: 292.86 | V9: 309.03 | W9: 166.4 | X9: 321.26 | Y9: 473.59
A10: 8558 | B10: 0 | C10: 0 | D10: 0 | E10: 0 | F10: 0 | G10: 131.4 | H10: 332.79 | I10: 154.85 | J10: 172.58 | K10: 151.87 | L10: 305.89 | M10: 454 | N10: 499.25 | O10: 117.75 | P10: 483.02 | Q10: 456.69 | R10: 281.62 | S10: 195.74 | T10: 435.76 | U10: 244.72 | V10: 225.93 | W10: 215.79 | X10: 358.91 | Y10: 525.02
A11: 8559 | B11: 0 | C11: 0 | D11: 0 | E11: 0 | F11: 0 | G11: 85.02 | H11: 92.48 | I11: 67.3 | J11: 63.22 | K11: 67.94 | L11: 131.71 | M11: 173.41 | N11: 247.92 | O11: 108.06 | P11: 101.19 | Q11: 77.36 | R11: 93.5 | S11: 135.59 | T11: 150.61 | U11: 101.26 | V11: 83.58 | W11: 92.95 | X11: 164.49 | Y11: 244.04
A12: 8560 | B12: 0 | C12: 0 | D12: 0 | E12: 0 | F12: 0 | G12: 51.19 | H12: 153.54 | I12: 125.01 | J12: 130.52 | K12: 91.61 | L12: 150.09 | M12: 209.74 | N12: 185.37 | O12: 131.51 | P12: 105.59 | Q12: 72.64 | R12: 89.99 | S12: 123.52 | T12: 213.59 | U12: 175.89 | V12: 185.75 | W12: 115.98 | X12: 187.53 | Y12: 400.32
A13: 8561 | B13: 0 | C13: 0 | D13: 0 | E13: 0 | F13: 0 | G13: 114.46 | H13: 156.2 | I13: 110.71 | J13: 260.77 | K13: 179.33 | L13: 224.35 | M13: 412.73 | N13: 606.87 | O13: 152.73 | P13: 491.2 | Q13: 404.96 | R13: 240.01 | S13: 180.49 | T13: 212.19 | U13: 175.43 | V13: 339.01 | W13: 251.07 | X13: 287 | Y13: 499.04
... A137: 8730 | B137: 0 | C137: 0 | D137: 0 | E137: 0 | F137: 480.78 | G137: 869.3 | H137: 484.66 | I137: 499.94 | J137: 802.97 | K137: 1074.48 | L137: 997.35 | M137: 1001.22 | N137: 1957.85 | O137: 79.62 | P137: 1019.69 | Q137: 699.4 | R137: 233.98 | S137: 803.7 | T137: 716.71 | U137: 712.12 | V137: 540.74 | W137: 624.71 | X137: 0 | Y137: 0
