Workbook

Sheet Resumen
A1: RESUMEN 2.0TD · 136 facturas · abril 2026 · Transactiva 2000 S.L.
A2: APROBAR ≥30% · REVISAR 20–30% · RECHAZAR <20%. PC provisional (ámbar) → sustituir por real. Margen objetivo editable por factura en el Detalle.
A3: ⚙ OPTIMIZAR (converge al objetivo · freno mejor mes) ▶ | D3: INICIAL | E3: Margen obj. ▶ | F3: 0.3 | G3: Ganancia ▶ | H3: =SUM(K5:K140)
A4: Factura | B4: Cliente | C4: Nombre | D4: Prov. | E4: Margen abril | F4: Veredicto | G4: Margen hist. | H4: Cobrado hist. | I4: Qué revisar
A5: 8550 | B5: C02150 | C5: FUNDACIÓN FSU PROGRAMAS INTERNACIO | D5: Naturgy | E5: ='Detalle'!B15 | F5: ='Detalle'!D15 | G5: 0.2802 | H5: 2435.51 | I5: =IF('Detalle'!B15="","Falta PC real",IF('Detalle'!B15>=0.3,"OK · registrar",IF('Detalle'!B15>=0.2,"Revisar margen","Revisar PC/PV"))) | K5: ='Detalle'!AD15
A6: 8551 | B6: C02140 | C6: FUNDACIÓN FSU PROGRAMAS INTERNACIO | D6: Naturgy | E6: ='Detalle'!B29 | F6: ='Detalle'!D29 | G6: 0.2374 | H6: 2120.45 | I6: =IF('Detalle'!B29="","Falta PC real",IF('Detalle'!B29>=0.3,"OK · registrar",IF('Detalle'!B29>=0.2,"Revisar margen","Revisar PC/PV"))) | K6: ='Detalle'!AD29
A7: 8552 | B7: C02130 | C7: FUNDACIÓN FSU PROGRAMAS INTERNACIO | D7: Naturgy | E7: ='Detalle'!B43 | F7: ='Detalle'!D43 | G7: 0.3004 | H7: 3194.42 | I7: =IF('Detalle'!B43="","Falta PC real",IF('Detalle'!B43>=0.3,"OK · registrar",IF('Detalle'!B43>=0.2,"Revisar margen","Revisar PC/PV"))) | K7: ='Detalle'!AD43
A8: 8553 | B8: C02120 | C8: FUNDACIÓN FSU PROGRAMAS INTERNACIO | D8: Naturgy | E8: ='Detalle'!B57 | F8: ='Detalle'!D57 | G8: 0.2933 | H8: 2606.28 | I8: =IF('Detalle'!B57="","Falta PC real",IF('Detalle'!B57>=0.3,"OK · registrar",IF('Detalle'!B57>=0.2,"Revisar margen","Revisar PC/PV"))) | K8: ='Detalle'!AD57
A9: 8554 | B9: C02110 | C9: FUNDACIÓN FSU PROGRAMAS INTERNACIO | D9: Naturgy | E9: ='Detalle'!B71 | F9: ='Detalle'!D71 | G9: 0.3099 | H9: 5248.88 | I9: =IF('Detalle'!B71="","Falta PC real",IF('Detalle'!B71>=0.3,"OK · registrar",IF('Detalle'!B71>=0.2,"Revisar margen","Revisar PC/PV"))) | K9: ='Detalle'!AD71
A10: 8555 | B10: C02100 | C10: FUNDACIÓN FSU PROGRAMAS INTERNACIO | D10: Naturgy | E10: ='Detalle'!B85 | F10: ='Detalle'!D85 | G10: 0.3022 | H10: 1841.6 | I10: =IF('Detalle'!B85="","Falta PC real",IF('Detalle'!B85>=0.3,"OK · registrar",IF('Detalle'!B85>=0.2,"Revisar margen","Revisar PC/PV"))) | K10: ='Detalle'!AD85
A11: 8556 | B11: C02090 | C11: FUNDACIÓN FSU PROGRAMAS INTERNACIO | D11: Naturgy | E11: ='Detalle'!B99 | F11: ='Detalle'!D99 | G11: 0.2895 | H11: 2954.17 | I11: =IF('Detalle'!B99="","Falta PC real",IF('Detalle'!B99>=0.3,"OK · registrar",IF('Detalle'!B99>=0.2,"Revisar margen","Revisar PC/PV"))) | K11: ='Detalle'!AD99
A12: 8557 | B12: C02080 | C12: FUNDACIÓN FSU PROGRAMAS INTERNACIO | D12: Naturgy | E12: ='Detalle'!B113 | F12: ='Detalle'!D113 | I12: =IF('Detalle'!B113="","Falta PC real",IF('Detalle'!B113>=0.3,"OK · registrar",IF('Detalle'!B113>=0.2,"Revisar margen","Revisar PC/PV"))) | K12: ='Detalle'!AD113
A13: 8558 | B13: C02060 | C13: FUNDACIÓN FSU PROGRAMAS INTERNACIO | D13: Naturgy | E13: ='Detalle'!B127 | F13: ='Detalle'!D127 | G13: 0.293 | H13: 3233.11 | I13: =IF('Detalle'!B127="","Falta PC real",IF('Detalle'!B127>=0.3,"OK · registrar",IF('Detalle'!B127>=0.2,"Revisar margen","Revisar PC/PV"))) | K13: ='Detalle'!AD127
A14: 8559 | B14: C02040 | C14: FUNDACIÓN FSU PROGRAMAS INTERNACIO | D14: Naturgy | E14: ='Detalle'!B141 | F14: ='Detalle'!D141 | G14: 0.3314 | H14: 989.5 | I14: =IF('Detalle'!B141="","Falta PC real",IF('Detalle'!B141>=0.3,"OK · registrar",IF('Detalle'!B141>=0.2,"Revisar margen","Revisar PC/PV"))) | K14: ='Detalle'!AD141
A15: 8560 | B15: C02030 | C15: FUNDACIÓN FSU PROGRAMAS INTERNACIO | D15: Naturgy | E15: ='Detalle'!B155 | F15: ='Detalle'!D155 | G15: 0.2482 | H15: 837.32 | I15: =IF('Detalle'!B155="","Falta PC real",IF('Detalle'!B155>=0.3,"OK · registrar",IF('Detalle'!B155>=0.2,"Revisar margen","Revisar PC/PV"))) | K15: ='Detalle'!AD155
A16: 8561 | B16: C02020 | C16: FUNDACIÓN FSU PROGRAMAS INTERNACIO | D16: Naturgy | E16: ='Detalle'!B169 | F16: ='Detalle'!D169 | G16: 0.2981 | H16: 3102.69 | I16: =IF('Detalle'!B169="","Falta PC real",IF('Detalle'!B169>=0.3,"OK · registrar",IF('Detalle'!B169>=0.2,"Revisar margen","Revisar PC/PV"))) | K16: ='Detalle'!AD169
A17: 8562 | B17: C01970 | C17: FUNDACIÓN FSU PROGRAMAS INTERNACIO | D17: Naturgy | E17: ='Detalle'!B183 | F17: ='Detalle'!D183 | G17: 0.295 | H17: 2842.61 | I17: =IF('Detalle'!B183="","Falta PC real",IF('Detalle'!B183>=0.3,"OK · registrar",IF('Detalle'!B183>=0.2,"Revisar margen","Revisar PC/PV"))) | K17: ='Detalle'!AD183
A18: 8563 | B18: C01960 | C18: FUNDACIÓN FSU PROGRAMAS INTERNACIO | D18: Naturgy | E18: ='Detalle'!B197 | F18: ='Detalle'!D197 | G18: 0.3206 | H18: 3731.12 | I18: =IF('Detalle'!B197="","Falta PC real",IF('Detalle'!B197>=0.3,"OK · registrar",IF('Detalle'!B197>=0.2,"Revisar margen","Revisar PC/PV"))) | K18: ='Detalle'!AD197
A19: 8568 | B19: C01400 | C19: CHRISTOPH BLUME | D19: Naturgy | E19: ='Detalle'!B211 | F19: ='Detalle'!D211 | G19: 0.3031 | H19: 2280.53 | I19: =IF('Detalle'!B211="","Falta PC real",IF('Detalle'!B211>=0.3,"OK · registrar",IF('Detalle'!B211>=0.2,"Revisar margen","Revisar PC/PV"))) | K19: ='Detalle'!AD211
A20: 8569 | B20: C02560 | C20: PEDRO IVARS TRO 2018, S.L. | D20: Naturgy | E20: ='Detalle'!B230 | F20: ='Detalle'!D230 | G20: 0.354 | H20: 452.94 | I20: =IF('Detalle'!B230="","Falta PC real",IF('Detalle'!B230>=0.3,"OK · registrar",IF('Detalle'!B230>=0.2,"Revisar margen","Revisar PC/PV"))) | K20: ='Detalle'!AD230
A21: 8570 | B21: C02680 | C21: ALVARO DAVID OCHOA BIOSCA | D21: Naturgy | E21: ='Detalle'!B244 | F21: ='Detalle'!D244 | G21: 1 | H21: 2.65 | I21: =IF('Detalle'!B244="","Falta PC real",IF('Detalle'!B244>=0.3,"OK · registrar",IF('Detalle'!B244>=0.2,"Revisar margen","Revisar PC/PV"))) | K21: ='Detalle'!AD244
A22: 8571 | B22: C00700 | C22: ELEEN VELTHOVEN | D22: Naturgy | E22: ='Detalle'!B258 | F22: ='Detalle'!D258 | G22: 0.1991 | H22: 1674.46 | I22: =IF('Detalle'!B258="","Falta PC real",IF('Detalle'!B258>=0.3,"OK · registrar",IF('Detalle'!B258>=0.2,"Revisar margen","Revisar PC/PV"))) | K22: ='Detalle'!AD258
A23: 8572 | B23: C01280 | C23: Mª ISABEL HEVIA TENA | D23: Naturgy | E23: ='Detalle'!B277 | F23: ='Detalle'!D277 | G23: 0.3077 | H23: 2373.43 | I23: =IF('Detalle'!B277="","Falta PC real",IF('Detalle'!B277>=0.3,"OK · registrar",IF('Detalle'!B277>=0.2,"Revisar margen","Revisar PC/PV"))) | K23: ='Detalle'!AD277
A24: 8573 | B24: C01990 | C24: GERRIT JONGEJAN | D24: Naturgy | E24: ='Detalle'!B296 | F24: ='Detalle'!D296 | G24: 0.0538 | H24: 609.46 | I24: =IF('Detalle'!B296="","Falta PC real",IF('Detalle'!B296>=0.3,"OK · registrar",IF('Detalle'!B296>=0.2,"Revisar margen","Revisar PC/PV"))) | K24: ='Detalle'!AD296
A25: 8574 | B25: C03260 | C25: MICHAL CUKAN | D25: Naturgy | E25: ='Detalle'!B315 | F25: ='Detalle'!D315 | G25: 1 | H25: 0.86 | I25: =IF('Detalle'!B315="","Falta PC real",IF('Detalle'!B315>=0.3,"OK · registrar",IF('Detalle'!B315>=0.2,"Revisar margen","Revisar PC/PV"))) | K25: ='Detalle'!AD315
A26: 8575 | B26: C01140 | C26: DESIRÉ ANNA GUSTAAF SCHUTTER | D26: Naturgy | E26: ='Detalle'!B329 | F26: ='Detalle'!D329 | G26: 0.2556 | H26: 1316.57 | I26: =IF('Detalle'!B329="","Falta PC real",IF('Detalle'!B329>=0.3,"OK · registrar",IF('Detalle'!B329>=0.2,"Revisar margen","Revisar PC/PV"))) | K26: ='Detalle'!AD329
A27: 8579 | B27: C01350 | C27: CORDULA PETERS | D27: Naturgy | E27: ='Detalle'!B348 | F27: ='Detalle'!D348 | G27: 0.0004 | H27: 638.64 | I27: =IF('Detalle'!B348="","Falta PC real",IF('Detalle'!B348>=0.3,"OK · registrar",IF('Detalle'!B348>=0.2,"Revisar margen","Revisar PC/PV"))) | K27: ='Detalle'!AD348
A28: 8580 | B28: C00060 | C28: HV LUXO SA | D28: Naturgy | E28: ='Detalle'!B367 | F28: ='Detalle'!D367 | G28: 0.4727 | H28: 1556.34 | I28: =IF('Detalle'!B367="","Falta PC real",IF('Detalle'!B367>=0.3,"OK · registrar",IF('Detalle'!B367>=0.2,"Revisar margen","Revisar PC/PV"))) | K28: ='Detalle'!AD367
A29: 8581 | C29: MANUEL GARCÍA DEL VALLE CARLOS-ROC | D29: Naturgy | E29: ='Detalle'!B386 | F29: ='Detalle'!D386 | G29: 0.178 | H29: 3463.21 | I29: =IF('Detalle'!B386="","Falta PC real",IF('Detalle'!B386>=0.3,"OK · registrar",IF('Detalle'!B386>=0.2,"Revisar margen","Revisar PC/PV"))) | K29: ='Detalle'!AD386
A30: 8584 | B30: C00040 | C30: Mª ROSARIO ORTOLÁ FERRER | D30: Naturgy | E30: ='Detalle'!B400 | F30: ='Detalle'!D400 | G30: 0.3577 | H30: 10840.8 | I30: =IF('Detalle'!B400="","Falta PC real",IF('Detalle'!B400>=0.3,"OK · registrar",IF('Detalle'!B400>=0.2,"Revisar margen","Revisar PC/PV"))) | K30: ='Detalle'!AD400
A31: 8585 | B31: C00050 | C31: HELADOS ESPI | D31: Naturgy | E31: ='Detalle'!B419 | F31: ='Detalle'!D419 | G31: 0.301 | H31: 5330.72 | I31: =IF('Detalle'!B419="","Falta PC real",IF('Detalle'!B419>=0.3,"OK · registrar",IF('Detalle'!B419>=0.2,"Revisar margen","Revisar PC/PV"))) | K31: ='Detalle'!AD419
A32: 8586 | B32: C00060 | C32: HV LUXO SA | D32: Naturgy | E32: ='Detalle'!B438 | F32: ='Detalle'!D438 | G32: 0.4727 | H32: 1556.34 | I32: =IF('Detalle'!B438="","Falta PC real",IF('Detalle'!B438>=0.3,"OK · registrar",IF('Detalle'!B438>=0.2,"Revisar margen","Revisar PC/PV"))) | K32: ='Detalle'!AD438
A33: 8588 | B33: C00100 | C33: CRISTINA MARÍA FALCÓN ESCALONA | D33: Naturgy | E33: ='Detalle'!B457 | F33: ='Detalle'!D457 | G33: 0.4676 | H33: 1874.26 | I33: =IF('Detalle'!B457="","Falta PC real",IF('Detalle'!B457>=0.3,"OK · registrar",IF('Detalle'!B457>=0.2,"Revisar margen","Revisar PC/PV"))) | K33: ='Detalle'!AD457
A34: 8589 | B34: C00120 | C34: STEPHEN RICHARD ROBINSON | D34: Naturgy | E34: ='Detalle'!B476 | F34: ='Detalle'!D476 | G34: 0.3197 | H34: 3583.48 | I34: =IF('Detalle'!B476="","Falta PC real",IF('Detalle'!B476>=0.3,"OK · registrar",IF('Detalle'!B476>=0.2,"Revisar margen","Revisar PC/PV"))) | K34: ='Detalle'!AD476
A35: 8590 | B35: C00130 | C35: BIO JARDINSOSTENIBLE, S.L.U. | D35: Naturgy | E35: ='Detalle'!B495 | F35: ='Detalle'!D495 | G35: 0.4296 | H35: 3448.6 | I35: =IF('Detalle'!B495="","Falta PC real",IF('Detalle'!B495>=0.3,"OK · registrar",IF('Detalle'!B495>=0.2,"Revisar margen","Revisar PC/PV"))) | K35: ='Detalle'!AD495
A36: 8593 | B36: C00270 | C36: CLAUDE JOSÉ GOFFINET | D36: Naturgy | E36: ='Detalle'!B514 | F36: ='Detalle'!D514 | G36: 0.46 | H36: 4468.12 | I36: =IF('Detalle'!B514="","Falta PC real",IF('Detalle'!B514>=0.3,"OK · registrar",IF('Detalle'!B514>=0.2,"Revisar margen","Revisar PC/PV"))) | K36: ='Detalle'!AD514
A37: 8594 | B37: C00310 | C37: MICHAEL BALMER | D37: Naturgy | E37: ='Detalle'!B533 | F37: ='Detalle'!D533 | G37: 0.5097 | H37: 1087.08 | I37: =IF('Detalle'!B533="","Falta PC real",IF('Detalle'!B533>=0.3,"OK · registrar",IF('Detalle'!B533>=0.2,"Revisar margen","Revisar PC/PV"))) | K37: ='Detalle'!AD533
A38: 8597 | B38: C00410 | C38: VALENTINA BARCA | D38: Naturgy | E38: ='Detalle'!B552 | F38: ='Detalle'!D552 | G38: 0.3904 | H38: 3173.99 | I38: =IF('Detalle'!B552="","Falta PC real",IF('Detalle'!B552>=0.3,"OK · registrar",IF('Detalle'!B552>=0.2,"Revisar margen","Revisar PC/PV"))) | K38: ='Detalle'!AD552
A39: 8599 | B39: C00540 | C39: PEDRO CAÑADAS FERNANDEZ | D39: Naturgy | E39: ='Detalle'!B571 | F39: ='Detalle'!D571 | G39: 0.2884 | H39: 910.46 | I39: =IF('Detalle'!B571="","Falta PC real",IF('Detalle'!B571>=0.3,"OK · registrar",IF('Detalle'!B571>=0.2,"Revisar margen","Revisar PC/PV"))) | K39: ='Detalle'!AD571
A40: 8600 | B40: C00670 | C40: CARLOS A. GAVILANES PAUCAR | D40: Naturgy | E40: ='Detalle'!B590 | F40: ='Detalle'!D590 | G40: 0.4352 | H40: 5027.47 | I40: =IF('Detalle'!B590="","Falta PC real",IF('Detalle'!B590>=0.3,"OK · registrar",IF('Detalle'!B590>=0.2,"Revisar margen","Revisar PC/PV"))) | K40: ='Detalle'!AD590
...

Sheet Detalle
A1: VALIDACIÓN FACTURAS 2.0TD · abril 2026 · Transactiva 2000 S.L. (Días = solo potencia/alquiler/bono · PC ámbar editable · margen objetivo editable por factura)
A3: Factura 8550 · C02150 · FUNDACIÓN FSU PROGRAMAS INTERNACIONALES | H3: ES0021000020111640FT · Naturgy | L3: 46113 | M3: a | N3: 46142 | R3: HISTÓRICO DEL CUPS · HOJA TTVA LUZ
A4: Concepto | B4: PENDIENTE (sin registrar) | H4: MES ANTERIOR · Fact.6304 | L4: AÑO ANTERIOR · Fact.4583 | R4: Cobrado total: 2.436 €
B5: Cant | C5: Días | D5: PC real | E5: PV | F5: Importe | H5: Cant | I5: PV | J5: Importe | L5: Cant | M5: PV | N5: Importe | R5: Pagado total: 1.753 €
A6: P1 Potencia | B6: 10.392 | C6: =$N$3-$L$3+1 | D6: 3.68919 | E6: 4.82 | F6: =ROUND(B6*E6,2) | H6: 10.392 | I6: 4.82 | J6: =ROUND(H6*I6,2) | L6: 10.392 | M6: 4.82 | N6: =ROUND(L6*M6,2) | R6: DIF: 682 € · Margen hist.: 28.0%
A7: P2 Potencia | B7: 10.392 | C7: =$N$3-$L$3+1 | D7: 1.31928 | E7: 2.37 | F7: =ROUND(B7*E7,2) | H7: 10.392 | I7: 2.37 | J7: =ROUND(H7*I7,2) | L7: 10.392 | M7: 2.37 | N7: =ROUND(L7*M7,2) | R7: Mejor mes: 2024-09 · 526 € · margen 197%
A8: P1 Energía | B8: =IF($P$8<>"",ROUND(AA8*(($AB$8/(1-$P$8))-74.7185)/113.0879,2),IF('Resumen'!$D$3="OPTIMIZAR",ROUND(MAX(AA8,MIN(AA8*(($AB$8/(1-'Resumen'!$F$3))-74.7185)/113.0879,AA8*(439.4393)/113.0879)),3),AA8)) | D8: 0.111171 | E8: 0.17 | F8: =ROUND(B8*E8,2) | H8: 477.269 | I8: 0.175 | J8: =ROUND(H8*I8,2) | L8: 95.263 | M8: 0.175 | N8: =ROUND(L8*M8,2) | O8: Margen objetivo (edita % aquí) ▶ | R8: Peor mes: 2024-08 · 66 € · margen 66% | AA8: 195.263 | AB8: =B6*D6+B7*D7+AA8*D8+AA9*D9+AA10*D10
A9: P2 Energía | B9: =IF($P$8<>"",ROUND(AA9*(($AB$8/(1-$P$8))-74.7185)/113.0879,2),IF('Resumen'!$D$3="OPTIMIZAR",ROUND(MAX(AA9,MIN(AA9*(($AB$8/(1-'Resumen'!$F$3))-74.7185)/113.0879,AA9*(439.4393)/113.0879)),3),AA9)) | D9: 0.111171 | E9: 0.17 | F9: =ROUND(B9*E9,2) | H9: 460.686 | I9: 0.175 | J9: =ROUND(H9*I9,2) | L9: 99.672 | M9: 0.175 | N9: =ROUND(L9*M9,2) | O9: Cant. P1/P2/P3 energía suben | R9: Importe mensual cobrado (€) · 24 meses ▾ | AA9: 199.672
A10: P3 Energía | B10: =IF($P$8<>"",ROUND(AA10*(($AB$8/(1-$P$8))-74.7185)/113.0879,2),IF('Resumen'!$D$3="OPTIMIZAR",ROUND(MAX(AA10,MIN(AA10*(($AB$8/(1-'Resumen'!$F$3))-74.7185)/113.0879,AA10*(439.4393)/113.0879)),3),AA10)) | D10: 0.111171 | E10: 0.17 | F10: =ROUND(B10*E10,2) | H10: 525.938 | I10: 0.175 | J10: =ROUND(H10*I10,2) | L10: 170.288 | M10: 0.175 | N10: =ROUND(L10*M10,2) | O10: en proporción para ese margen | AA10: 270.288
A11: Alquiler contador | B11: 1 | C11: =$N$3-$L$3+1 | D11: 1.3414 | E11: 1 | F11: =ROUND(B11*E11,2) | H11: 1 | I11: 1 | J11: =ROUND(H11*I11,2) | L11: 1 | M11: 1 | N11: =ROUND(L11*M11,2)
A12: Bono social | B12: 30 | C12: =$N$3-$L$3+1 | D12: 0.5736 | E12: 0.01274 | F12: =ROUND(B12*E12,2) | H12: 30 | I12: 0.01274 | J12: =ROUND(H12*I12,2) | L12: 30 | M12: 0.00685 | N12: =ROUND(L12*M12,2)
A13: Tasa eléctrica | B13: 10.03 | D13: 0.27312 | E13: 1 | F13: =ROUND(B13*E13,2) | H13: 17.16 | I13: 1 | J13: =ROUND(H13*I13,2) | L13: 7.09 | M13: 1 | N13: =ROUND(L13*M13,2)
A14: TOTAL c/IVA | F14: =ROUND((SUM(F6:F13)-F13)*1.1+F13,2) | J14: =ROUND(SUM(J6:J13),2) | N14: =ROUND(SUM(N6:N13),2)
A15: MARGEN sin registrar | B15: =IF((F9+F6+F8+F10+F7)=0,"",((F9+F6+F8+F10+F7)-$AB$8)/(F9+F6+F8+F10+F7)) | D15: =IF(B15="","SIN PC",IF(B15>=0.3,"APROBAR",IF(B15>=0.2,"REVISAR","RECHAZAR"))) | AD15: =SUM(F8:F10)-113.0879
A17: Factura 8551 · C02140 · FUNDACIÓN FSU PROGRAMAS INTERNACIONALES | H17: ES0021000008997145KW · Naturgy | L17: 46113 | M17: a | N17: 46142 | R17: HISTÓRICO DEL CUPS · HOJA TTVA LUZ
A18: Concepto | B18: PENDIENTE (sin registrar) | H18: MES ANTERIOR · Fact.6308 | L18: AÑO ANTERIOR · Fact.4584 | R18: Cobrado total: 2.120 €
B19: Cant | C19: Días | D19: PC real | E19: PV | F19: Importe | H19: Cant | I19: PV | J19: Importe | L19: Cant | M19: PV | N19: Importe | R19: Pagado total: 1.617 €
A20: P1 Potencia | B20: 10.392 | C20: =$N$17-$L$17+1 | D20: 3.68919 | E20: 4.82 | F20: =ROUND(B20*E20,2) | H20: 10.392 | I20: 4.82 | J20: =ROUND(H20*I20,2) | L20: 10.392 | M20: 4.82 | N20: =ROUND(L20*M20,2) | R20: DIF: 503 € · Margen hist.: 23.7%
A21: P2 Potencia | B21: 10.392 | C21: =$N$17-$L$17+1 | D21: 1.31928 | E21: 2.37 | F21: =ROUND(B21*E21,2) | H21: 10.392 | I21: 2.37 | J21: =ROUND(H21*I21,2) | L21: 10.392 | M21: 2.37 | N21: =ROUND(L21*M21,2) | R21: Mejor mes: 2024-07 · 345 € · margen 79%
A22: P1 Energía | B22: =IF($P$22<>"",ROUND(AA22*(($AB$22/(1-$P$22))-74.7185)/100.7259,2),IF('Resumen'!$D$3="OPTIMIZAR",ROUND(MAX(AA22,MIN(AA22*(($AB$22/(1-'Resumen'!$F$3))-74.7185)/100.7259,AA22*(259.0793)/100.7259)),3),AA22)) | D22: 0.111171 | E22: 0.17 | F22: =ROUND(B22*E22,2) | H22: 309.614 | I22: 0.175 | J22: =ROUND(H22*I22,2) | L22: 77.5 | M22: 0.175 | N22: =ROUND(L22*M22,2) | O22: Margen objetivo (edita % aquí) ▶ | R22: Peor mes: 2024-08 · 84 € · margen 37% | AA22: 177.5 | AB22: =B20*D20+B21*D21+AA22*D22+AA23*D23+AA24*D24
A23: P2 Energía | B23: =IF($P$22<>"",ROUND(AA23*(($AB$22/(1-$P$22))-74.7185)/100.7259,2),IF('Resumen'!$D$3="OPTIMIZAR",ROUND(MAX(AA23,MIN(AA23*(($AB$22/(1-'Resumen'!$F$3))-74.7185)/100.7259,AA23*(259.0793)/100.7259)),3),AA23)) | D23: 0.111171 | E23: 0.17 | F23: =ROUND(B23*E23,2) | H23: 186.461 | I23: 0.175 | J23: =ROUND(H23*I23,2) | L23: 68.86 | M23: 0.175 | N23: =ROUND(L23*M23,2) | O23: Cant. P1/P2/P3 energía suben | R23: Importe mensual cobrado (€) · 24 meses ▾ | AA23: 168.86
A24: P3 Energía | B24: =IF($P$22<>"",ROUND(AA24*(($AB$22/(1-$P$22))-74.7185)/100.7259,2),IF('Resumen'!$D$3="OPTIMIZAR",ROUND(MAX(AA24,MIN(AA24*(($AB$22/(1-'Resumen'!$F$3))-74.7185)/100.7259,AA24*(259.0793)/100.7259)),3),AA24)) | D24: 0.111171 | E24: 0.17 | F24: =ROUND(B24*E24,2) | H24: 355.272 | I24: 0.175 | J24: =ROUND(H24*I24,2) | L24: 146.145 | M24: 0.175 | N24: =ROUND(L24*M24,2) | O24: en proporción para ese margen | AA24: 246.145
A25: Alquiler contador | B25: 1 | C25: =$N$17-$L$17+1 | D25: 1.3414 | E25: 1 | F25: =ROUND(B25*E25,2) | H25: 1 | I25: 1 | J25: =ROUND(H25*I25,2) | L25: 1 | M25: 1 | N25: =ROUND(L25*M25,2)
A26: Bono social | B26: 30 | C26: =$N$17-$L$17+1 | D26: 0.5736 | E26: 0.01274 | F26: =ROUND(B26*E26,2) | H26: 30 | I26: 0.01274 | J26: =ROUND(H26*I26,2) | L26: 30 | M26: 0.00685 | N26: =ROUND(L26*M26,2)
A27: Tasa eléctrica | B27: 9.37 | D27: 0.27312 | E27: 1 | F27: =ROUND(B27*E27,2) | H27: 12.1 | I27: 1 | J27: =ROUND(H27*I27,2) | L27: 6.44 | M27: 1 | N27: =ROUND(L27*M27,2)
A28: TOTAL c/IVA | F28: =ROUND((SUM(F20:F27)-F27)*1.1+F27,2) | J28: =ROUND(SUM(J20:J27),2) | N28: =ROUND(SUM(N20:N27),2)
A29: MARGEN sin registrar | B29: =IF((F23+F20+F22+F24+F21)=0,"",((F23+F20+F22+F24+F21)-$AB$22)/(F23+F20+F22+F24+F21)) | D29: =IF(B29="","SIN PC",IF(B29>=0.3,"APROBAR",IF(B29>=0.2,"REVISAR","RECHAZAR"))) | AD29: =SUM(F22:F24)-100.7259
A31: Factura 8552 · C02130 · FUNDACIÓN FSU PROGRAMAS INTERNACIONALES | H31: ES0021000012268833JD · Naturgy | L31: 46113 | M31: a | N31: 46142 | R31: HISTÓRICO DEL CUPS · HOJA TTVA LUZ
A32: Concepto | B32: PENDIENTE (sin registrar) | H32: MES ANTERIOR · Fact.6311 | L32: AÑO ANTERIOR · Fact.4585 | R32: Cobrado total: 3.194 €
B33: Cant | C33: Días | D33: PC real | E33: PV | F33: Importe | H33: Cant | I33: PV | J33: Importe | L33: Cant | M33: PV | N33: Importe | R33: Pagado total: 2.235 €
A34: P1 Potencia | B34: 6.928 | C34: =$N$31-$L$31+1 | D34: 3.68919 | E34: 4.82 | F34: =ROUND(B34*E34,2) | H34: 6.928 | I34: 4.82 | J34: =ROUND(H34*I34,2) | L34: 6.928 | M34: 4.82 | N34: =ROUND(L34*M34,2) | R34: DIF: 960 € · Margen hist.: 30.0%
A35: P2 Potencia | B35: 6.928 | C35: =$N$31-$L$31+1 | D35: 1.31928 | E35: 2.37 | F35: =ROUND(B35*E35,2) | H35: 6.928 | I35: 2.37 | J35: =ROUND(H35*I35,2) | L35: 6.928 | M35: 2.37 | N35: =ROUND(L35*M35,2) | R35: Mejor mes: 2024-07 · 613 € · margen 71%
A36: P1 Energía | B36: =IF($P$36<>"",ROUND(AA36*(($AB$36/(1-$P$36))-49.8123)/207.1457,2),IF('Resumen'!$D$3="OPTIMIZAR",ROUND(MAX(AA36,MIN(AA36*(($AB$36/(1-'Resumen'!$F$3))-49.8123)/207.1457,AA36*(548.5955)/207.1457)),3),AA36)) | D36: 0.111171 | E36: 0.17 | F36: =ROUND(B36*E36,2) | H36: 250.417 | I36: 0.175 | J36: =ROUND(H36*I36,2) | L36: 201.884 | M36: 0.175 | N36: =ROUND(L36*M36,2) | O36: Margen objetivo (edita % aquí) ▶ | R36: Peor mes: 2024-08 · 129 € · margen 25% | AA36: 301.884 | AB36: =B34*D34+B35*D35+AA36*D36+AA37*D37+AA38*D38
A37: P2 Energía | B37: =IF($P$36<>"",ROUND(AA37*(($AB$36/(1-$P$36))-49.8123)/207.1457,2),IF('Resumen'!$D$3="OPTIMIZAR",ROUND(MAX(AA37,MIN(AA37*(($AB$36/(1-'Resumen'!$F$3))-49.8123)/207.1457,AA37*(548.5955)/207.1457)),3),AA37)) | D37: 0.111171 | E37: 0.17 | F37: =ROUND(B37*E37,2) | H37: 234.006 | I37: 0.175 | J37: =ROUND(H37*I37,2) | L37: 174.313 | M37: 0.175 | N37: =ROUND(L37*M37,2) | O37: Cant. P1/P2/P3 energía suben | R37: Importe mensual cobrado (€) · 24 meses ▾ | AA37: 374.313
A38: P3 Energía | B38: =IF($P$36<>"",ROUND(AA38*(($AB$36/(1-$P$36))-49.8123)/207.1457,2),IF('Resumen'!$D$3="OPTIMIZAR",ROUND(MAX(AA38,MIN(AA38*(($AB$36/(1-'Resumen'!$F$3))-49.8123)/207.1457,AA38*(548.5955)/207.1457)),3),AA38)) | D38: 0.111171 | E38: 0.17 | F38: =ROUND(B38*E38,2) | H38: 376.925 | I38: 0.175 | J38: =ROUND(H38*I38,2) | L38: 342.307 | M38: 0.175 | N38: =ROUND(L38*M38,2) | O38: en proporción para ese margen | AA38: 542.307
A39: Alquiler contador | B39: 1 | C39: =$N$31-$L$31+1 | D39: 1.3414 | E39: 1 | F39: =ROUND(B39*E39,2) | H39: 1 | I39: 1 | J39: =ROUND(H39*I39,2) | L39: 1 | M39: 1 | N39: =ROUND(L39*M39,2)
A40: Bono social | B40: 30 | C40: =$N$31-$L$31+1 | D40: 0.5736 | E40: 0.01274 | F40: =ROUND(B40*E40,2) | H40: 30 | I40: 0.01274 | J40: =ROUND(H40*I40,2) | L40: 30 | M40: 0.00685 | N40: =ROUND(L40*M40,2)
A41: Tasa eléctrica | B41: 13.65 | D41: 0.27312 | E41: 1 | F41: =ROUND(B41*E41,2) | H41: 12.86 | I41: 1 | J41: =ROUND(H41*I41,2) | L41: 8.83 | M41: 1 | N41: =ROUND(L41*M41,2)
A42: TOTAL c/IVA | F42: =ROUND((SUM(F34:F41)-F41)*1.1+F41,2) | J42: =ROUND(SUM(J34:J41),2) | N42: =ROUND(SUM(N34:N41),2)
A43: MARGEN sin registrar | B43: =IF((F37+F34+F36+F38+F35)=0,"",((F37+F34+F36+F38+F35)-$AB$36)/(F37+F34+F36+F38+F35)) | D43: =IF(B43="","SIN PC",IF(B43>=0.3,"APROBAR",IF(B43>=0.2,"REVISAR","RECHAZAR"))) | AD43: =SUM(F36:F38)-207.1457
...

Sheet _series
A1: nf | B1: 2024-07 | C1: 2024-08 | D1: 2024-09 | E1: 2024-10 | F1: 2024-11 | G1: 2024-12 | H1: 2025-01 | I1: 2025-02 | J1: 2025-03 | K1: 2025-04 | L1: 2025-05 | M1: 2025-06 | N1: 2025-07 | O1: 2025-08 | P1: 2025-09 | Q1: 2025-10 | R1: 2025-11 | S1: 2025-12 | T1: 2026-01 | U1: 2026-02 | V1: 2026-03 | W1: 2026-04 | X1: 2026-05 | Y1: 2026-06
A2: 8550 | B2: 0 | C2: 0 | D2: 0 | E2: 0 | F2: 0 | G2: 67.85 | H2: 291.23 | I2: 212.91 | J2: 183.41 | K2: 146.93 | L2: 240.12 | M2: 360.36 | N2: 489.63 | O2: 103.62 | P2: 664.91 | Q2: 334.22 | R2: 254.97 | S2: 121.53 | T2: 392.65 | U2: 287.51 | V2: 349.44 | W2: 199.21 | X2: 273.87 | Y2: 430.03
A3: 8551 | B3: 0 | C3: 0 | D3: 0 | E3: 0 | F3: 0 | G3: 122.79 | H3: 257.6 | I3: 149.89 | J3: 179.34 | K3: 133.56 | L3: 217.18 | M3: 255.1 | N3: 355.24 | O3: 132.59 | P3: 333.79 | Q3: 306.02 | R3: 209.78 | S3: 189.38 | T3: 339.72 | U3: 188.55 | V3: 237.18 | W3: 186.2 | X3: 276 | Y3: 343.77
A4: 8552 | B4: 0 | C4: 0 | D4: 0 | E4: 0 | F4: 0 | G4: 240.78 | H4: 270.33 | I4: 122.02 | J4: 156.75 | K4: 185.58 | L4: 220.94 | M4: 589.63 | N4: 626.48 | O4: 164.89 | P4: 386.56 | Q4: 382.69 | R4: 261.9 | S4: 330.96 | T4: 371.28 | U4: 169.53 | V4: 214.78 | W4: 271.98 | X4: 271.88 | Y4: 692.94
A5: 8553 | B5: 0 | C5: 0 | D5: 0 | E5: 0 | F5: 0 | G5: 143.34 | H5: 255.18 | I5: 122.89 | J5: 228.55 | K5: 175.12 | L5: 270.51 | M5: 388.07 | N5: 574.82 | O5: 154.53 | P5: 359.42 | Q5: 352.4 | R5: 177.06 | S5: 261.13 | T5: 337.12 | U5: 149.42 | V5: 232.63 | W5: 279.54 | X5: 333.42 | Y5: 462.7
A6: 8554 | B6: 0 | C6: 0 | D6: 0 | E6: 0 | F6: 0 | G6: 181.06 | H6: 235.48 | I6: 115.38 | J6: 164.69 | K6: 208.48 | L6: 620.36 | M6: 776.69 | N6: 910.68 | O6: 276.4 | P6: 777.08 | Q6: 555.31 | R6: 267.98 | S6: 240.42 | T6: 316.78 | U6: 165.48 | V6: 218.11 | W6: 311.55 | X6: 651.31 | Y6: 839.16
A7: 8555 | B7: 0 | C7: 0 | D7: 0 | E7: 0 | F7: 0 | G7: 98.79 | H7: 169.59 | I7: 113.34 | J7: 142.42 | K7: 111.81 | L7: 150.31 | M7: 280.5 | N7: 374.5 | O7: 130.26 | P7: 333.66 | Q7: 240.63 | R7: 117.47 | S7: 166.39 | T7: 229.98 | U7: 152.99 | V7: 196.1 | W7: 164.11 | X7: 189.25 | Y7: 351.03
A8: 8556 | B8: 0 | C8: 0 | D8: 0 | E8: 0 | F8: 0 | G8: 170.28 | H8: 258.52 | I8: 181.42 | J8: 255.74 | K8: 242.83 | L8: 303.68 | M8: 367.91 | N8: 611.02 | O8: 163.33 | P8: 392.33 | Q8: 376.51 | R8: 126.21 | S8: 230.73 | T8: 340.4 | U8: 259.71 | V8: 311.91 | W8: 314.39 | X8: 371.77 | Y8: 505.17
A9: 8557 | B9: 0 | C9: 0 | D9: 0 | E9: 0 | F9: 0 | G9: 193.05 | H9: 309.11 | I9: 197.99 | J9: 256.8 | K9: 114.01 | L9: 245.88 | M9: 405.6 | N9: 510.83 | O9: 181.08 | P9: 334.97 | Q9: 263.34 | R9: 146.93 | S9: 251.21 | T9: 411.51 | U9: 292.86 | V9: 309.03 | W9: 166.4 | X9: 321.26 | Y9: 473.59
A10: 8558 | B10: 0 | C10: 0 | D10: 0 | E10: 0 | F10: 0 | G10: 131.4 | H10: 332.79 | I10: 154.85 | J10: 172.58 | K10: 151.87 | L10: 305.89 | M10: 454 | N10: 499.25 | O10: 117.75 | P10: 483.02 | Q10: 456.69 | R10: 281.62 | S10: 195.74 | T10: 435.76 | U10: 244.72 | V10: 225.93 | W10: 215.79 | X10: 358.91 | Y10: 525.02
A11: 8559 | B11: 0 | C11: 0 | D11: 0 | E11: 0 | F11: 0 | G11: 85.02 | H11: 92.48 | I11: 67.3 | J11: 63.22 | K11: 67.94 | L11: 131.71 | M11: 173.41 | N11: 247.92 | O11: 108.06 | P11: 101.19 | Q11: 77.36 | R11: 93.5 | S11: 135.59 | T11: 150.61 | U11: 101.26 | V11: 83.58 | W11: 92.95 | X11: 164.49 | Y11: 244.04
A12: 8560 | B12: 0 | C12: 0 | D12: 0 | E12: 0 | F12: 0 | G12: 51.19 | H12: 153.54 | I12: 125.01 | J12: 130.52 | K12: 91.61 | L12: 150.09 | M12: 209.74 | N12: 185.37 | O12: 131.51 | P12: 105.59 | Q12: 72.64 | R12: 89.99 | S12: 123.52 | T12: 213.59 | U12: 175.89 | V12: 185.75 | W12: 115.98 | X12: 187.53 | Y12: 400.32
A13: 8561 | B13: 0 | C13: 0 | D13: 0 | E13: 0 | F13: 0 | G13: 114.46 | H13: 156.2 | I13: 110.71 | J13: 260.77 | K13: 179.33 | L13: 224.35 | M13: 412.73 | N13: 606.87 | O13: 152.73 | P13: 491.2 | Q13: 404.96 | R13: 240.01 | S13: 180.49 | T13: 212.19 | U13: 175.43 | V13: 339.01 | W13: 251.07 | X13: 287 | Y13: 499.04
... A137: 8730 | B137: 0 | C137: 0 | D137: 0 | E137: 0 | F137: 480.78 | G137: 869.3 | H137: 484.66 | I137: 499.94 | J137: 802.97 | K137: 1074.48 | L137: 997.35 | M137: 1001.22 | N137: 1957.85 | O137: 79.62 | P137: 1019.69 | Q137: 699.4 | R137: 233.98 | S137: 803.7 | T137: 716.71 | U137: 712.12 | V137: 540.74 | W137: 624.71 | X137: 0 | Y137: 0
