Workbook

Sheet Resumen
A1: RESUMEN · 27 facturas 3.0TD · abril 2026 · margen abril vivo (editable) + histórico del CUPS (HOJA TTVA LUZ)
A2: LEYENDA | B2: APROBAR ≥30% | D2: REVISAR 20–30% | F2: RECHAZAR <20% · margen objetivo editable en Detalle
A4: Factura | B4: Cliente | C4: Nombre | D4: Prov. | E4: Margen abril | F4: Veredicto | G4: Margen hist. | H4: Cobrado hist. | I4: Qué revisar
A5: 8544 | B5: C02330 | C5: ORENCO 2019, S.L. | D5: Naturgy | E5: =Detalle!B17 -> 0.17898769 | F5: =IF(Detalle!B17>=0.3,"APROBAR",IF(Detalle!B17>=0.2,"REVISAR","RECHAZAR")) -> RECHAZAR | G5: 0.275 | H5: 40716.44 | I5: =IF(Detalle!B17>=0.3,"OK · registrar",IF(Detalle!B17>=0.2,"Margen abril <30%","Margen abril <20% · subir objetivo o renegociar"))&"" -> Margen abril <20% · subir objetivo o renegociar
A6: 8545 | B6: C01200 | C6: SOLUCIONES GASTRONÓMICAS DE JAVEA 2014, S.L. | D6: Naturgy | E6: =Detalle!B35 -> 0.20960183 | F6: =IF(Detalle!B35>=0.3,"APROBAR",IF(Detalle!B35>=0.2,"REVISAR","RECHAZAR")) -> REVISAR | G6: 0.244 | H6: 53718.09 | I6: =IF(Detalle!B35>=0.3,"OK · registrar",IF(Detalle!B35>=0.2,"Margen abril <30%","Margen abril <20% · subir objetivo o renegociar"))&"" -> Margen abril <30%
A7: 8546 | B7: C03270 | C7: LULU BEACH CLUB JAVEA SL | D7: Naturgy | E7: =Detalle!B53 -> 0.033690116 | F7: =IF(Detalle!B53>=0.3,"APROBAR",IF(Detalle!B53>=0.2,"REVISAR","RECHAZAR")) -> RECHAZAR | G7: 0.204 | H7: 12272.46 | I7: =IF(Detalle!B53>=0.3,"OK · registrar",IF(Detalle!B53>=0.2,"Margen abril <30%","Margen abril <20% · subir objetivo o renegociar"))&"" -> Margen abril <20% · subir objetivo o renegociar
A8: 8547 | B8: C01770 | C8: CASA LILI JAVEA, S.L. | D8: ? | E8: =Detalle!B72 -> 0.30715088 | F8: =IF(Detalle!B72>=0.3,"APROBAR",IF(Detalle!B72>=0.2,"REVISAR","RECHAZAR")) -> APROBAR | G8: 0.432 | H8: 130568.72 | I8: =IF(Detalle!B72>=0.3,"OK · registrar",IF(Detalle!B72>=0.2,"Margen abril <30%","Margen abril <20% · subir objetivo o renegociar"))&" · Es 6.1TD (no 3.0TD)" -> OK · registrar · Es 6.1TD (no 3.0TD)
A9: 8564 | B9: C01930 | C9: FUNDACIÓN FSU PROGRAMAS INTERNACIONALES | D9: Naturgy | E9: =Detalle!B90 -> 0.35858241 | F9: =IF(Detalle!B90>=0.3,"APROBAR",IF(Detalle!B90>=0.2,"REVISAR","RECHAZAR")) -> APROBAR | G9: 0.269 | H9: 18857.1 | I9: =IF(Detalle!B90>=0.3,"OK · registrar",IF(Detalle!B90>=0.2,"Margen abril <30%","Margen abril <20% · subir objetivo o renegociar"))&"" -> OK · registrar
A10: 8565 | B10: C01920 | C10: FUNDACIÓN FSU PROGRAMAS INTERNACIONALES | D10: Naturgy | E10: =Detalle!B108 -> 0.33436081 | F10: =IF(Detalle!B108>=0.3,"APROBAR",IF(Detalle!B108>=0.2,"REVISAR","RECHAZAR")) -> APROBAR | G10: 0.324 | H10: 19336.5 | I10: =IF(Detalle!B108>=0.3,"OK · registrar",IF(Detalle!B108>=0.2,"Margen abril <30%","Margen abril <20% · subir objetivo o renegociar"))&"" -> OK · registrar
A11: 8566 | B11: C01910 | C11: FUNDACIÓN FSU PROGRAMAS INTERNACIONALES | D11: Naturgy | E11: =Detalle!B126 -> 0.32661503 | F11: =IF(Detalle!B126>=0.3,"APROBAR",IF(Detalle!B126>=0.2,"REVISAR","RECHAZAR")) -> APROBAR | G11: 0.342 | H11: 10564.26 | I11: =IF(Detalle!B126>=0.3,"OK · registrar",IF(Detalle!B126>=0.2,"Margen abril <30%","Margen abril <20% · subir objetivo o renegociar"))&"" -> OK · registrar
A12: 8567 | B12: C00790 | C12: CASA LILI, S.L. | D12: Naturgy | E12: =Detalle!B145 -> 0.16289997 | F12: =IF(Detalle!B145>=0.3,"APROBAR",IF(Detalle!B145>=0.2,"REVISAR","RECHAZAR")) -> RECHAZAR | G12: 0.405 | H12: 151868.44 | I12: =IF(Detalle!B145>=0.3,"OK · registrar",IF(Detalle!B145>=0.2,"Margen abril <30%","Margen abril <20% · subir objetivo o renegociar"))&"" -> Margen abril <20% · subir objetivo o renegociar
A13: 8578 | B13: C02180 | C13: EDWIN BAUMGARTNER | D13: Naturgy | E13: =Detalle!B163 -> 0.30823789 | F13: =IF(Detalle!B163>=0.3,"APROBAR",IF(Detalle!B163>=0.2,"REVISAR","RECHAZAR")) -> APROBAR | G13: 0.487 | H13: 2907.71 | I13: =IF(Detalle!B163>=0.3,"OK · registrar",IF(Detalle!B163>=0.2,"Margen abril <30%","Margen abril <20% · subir objetivo o renegociar"))&"" -> OK · registrar
A14: 8615 | B14: C01220 | C14: VIVES ELECTRODOMÉSTICOS, S.L. | D14: Repsol | E14: =Detalle!B181 -> 0.13307223 | F14: =IF(Detalle!B181>=0.3,"APROBAR",IF(Detalle!B181>=0.2,"REVISAR","RECHAZAR")) -> RECHAZAR | G14: 0.316 | H14: 26924.82 | I14: =IF(Detalle!B181>=0.3,"OK · registrar",IF(Detalle!B181>=0.2,"Margen abril <30%","Margen abril <20% · subir objetivo o renegociar"))&" · Repsol margen muy bajo" -> Margen abril <20% · subir objetivo o renegociar · Repsol margen muy bajo
A15: 8629 | B15: C01510 | C15: CAFE ZUR BACKSTUBE, S.L. | D15: Naturgy | E15: =Detalle!B199 -> 0.29787383 | F15: =IF(Detalle!B199>=0.3,"APROBAR",IF(Detalle!B199>=0.2,"REVISAR","RECHAZAR")) -> REVISAR | G15: 0.362 | H15: 6192.61 | I15: =IF(Detalle!B199>=0.3,"OK · registrar",IF(Detalle!B199>=0.2,"Margen abril <30%","Margen abril <20% · subir objetivo o renegociar"))&"" -> Margen abril <30%
A16: 8635 | B16: C01630 | C16: ALEJANDRO BOX CANDELA | D16: Naturgy | E16: =Detalle!B217 -> 0.16804865 | F16: =IF(Detalle!B217>=0.3,"APROBAR",IF(Detalle!B217>=0.2,"REVISAR","RECHAZAR")) -> RECHAZAR | G16: 0.277 | H16: 31335.42 | I16: =IF(Detalle!B217>=0.3,"OK · registrar",IF(Detalle!B217>=0.2,"Margen abril <30%","Margen abril <20% · subir objetivo o renegociar"))&"" -> Margen abril <20% · subir objetivo o renegociar
A17: 8638 | B17: C01710 | C17: FARMACIA ESPINÓS | D17: Repsol | E17: =Detalle!B235 -> 0.16678386 | F17: =IF(Detalle!B235>=0.3,"APROBAR",IF(Detalle!B235>=0.2,"REVISAR","RECHAZAR")) -> RECHAZAR | G17: 0.253 | H17: 14704.48 | I17: =IF(Detalle!B235>=0.3,"OK · registrar",IF(Detalle!B235>=0.2,"Margen abril <30%","Margen abril <20% · subir objetivo o renegociar"))&"" -> Margen abril <20% · subir objetivo o renegociar
A18: 8644 | B18: C01840 | C18: JOSE GUILLERMO CHOLBI SART | D18: Naturgy | E18: =Detalle!B253 -> 0.33509687 | F18: =IF(Detalle!B253>=0.3,"APROBAR",IF(Detalle!B253>=0.2,"REVISAR","RECHAZAR")) -> APROBAR | G18: 0.184 | H18: 3367.63 | I18: =IF(Detalle!B253>=0.3,"OK · registrar",IF(Detalle!B253>=0.2,"Margen abril <30%","Margen abril <20% · subir objetivo o renegociar"))&"" -> OK · registrar
A19: 8649 | B19: C01980 | C19: TINTORERÍA LAVANDERÍA COLOMER | D19: Repsol | E19: =Detalle!B271 -> 0.21949185 | F19: =IF(Detalle!B271>=0.3,"APROBAR",IF(Detalle!B271>=0.2,"REVISAR","RECHAZAR")) -> REVISAR | G19: 0.203 | H19: 15417.71 | I19: =IF(Detalle!B271>=0.3,"OK · registrar",IF(Detalle!B271>=0.2,"Margen abril <30%","Margen abril <20% · subir objetivo o renegociar"))&" · P6 a precio doble (real)" -> Margen abril <30% · P6 a precio doble (real)
A20: 8652 | B20: C02180 | C20: EDWIN BAUMGARTNER | D20: Naturgy | E20: =Detalle!B289 -> 0.30823789 | F20: =IF(Detalle!B289>=0.3,"APROBAR",IF(Detalle!B289>=0.2,"REVISAR","RECHAZAR")) -> APROBAR | G20: 0.487 | H20: 2907.71 | I20: =IF(Detalle!B289>=0.3,"OK · registrar",IF(Detalle!B289>=0.2,"Margen abril <30%","Margen abril <20% · subir objetivo o renegociar"))&"" -> OK · registrar
A21: 8669 | B21: C02600 | C21: CRISTIAN FERRARI | D21: Naturgy | E21: =Detalle!B307 -> 0.2360357 | F21: =IF(Detalle!B307>=0.3,"APROBAR",IF(Detalle!B307>=0.2,"REVISAR","RECHAZAR")) -> REVISAR | G21: 0.292 | H21: 5897.71 | I21: =IF(Detalle!B307>=0.3,"OK · registrar",IF(Detalle!B307>=0.2,"Margen abril <30%","Margen abril <20% · subir objetivo o renegociar"))&"" -> Margen abril <30%
A22: 8684 | B22: C02910 | C22: NICHOLAS JAMES RATCLIFFE | D22: Repsol | E22: =Detalle!B325 -> 0.25181786 | F22: =IF(Detalle!B325>=0.3,"APROBAR",IF(Detalle!B325>=0.2,"REVISAR","RECHAZAR")) -> REVISAR | G22: 0.424 | H22: 4741.93 | I22: =IF(Detalle!B325>=0.3,"OK · registrar",IF(Detalle!B325>=0.2,"Margen abril <30%","Margen abril <20% · subir objetivo o renegociar"))&"" -> Margen abril <30%
A23: 8691 | B23: C03020 | C23: MONTGO SEGURIDAD S.L. | D23: Repsol | E23: =Detalle!B343 -> 0.07172886 | F23: =IF(Detalle!B343>=0.3,"APROBAR",IF(Detalle!B343>=0.2,"REVISAR","RECHAZAR")) -> RECHAZAR | G23: 0.154 | H23: 2756.73 | I23: =IF(Detalle!B343>=0.3,"OK · registrar",IF(Detalle!B343>=0.2,"Margen abril <30%","Margen abril <20% · subir objetivo o renegociar"))&"" -> Margen abril <20% · subir objetivo o renegociar
A24: 8705 | B24: C03200 | C24: 2 HANDS FULL, S.L | D24: Repsol | E24: =Detalle!B361 -> 0.069009331 | F24: =IF(Detalle!B361>=0.3,"APROBAR",IF(Detalle!B361>=0.2,"REVISAR","RECHAZAR")) -> RECHAZAR | G24: 0.147 | H24: 3844.21 | I24: =IF(Detalle!B361>=0.3,"OK · registrar",IF(Detalle!B361>=0.2,"Margen abril <30%","Margen abril <20% · subir objetivo o renegociar"))&"" -> Margen abril <20% · subir objetivo o renegociar
A25: 8731 | B25: C01500 | C25: SANTIAGO JAVIER NUÑEZ JOVER | D25: Repsol | E25: =Detalle!B379 -> 0.163502 | F25: =IF(Detalle!B379>=0.3,"APROBAR",IF(Detalle!B379>=0.2,"REVISAR","RECHAZAR")) -> RECHAZAR | G25: 0.306 | H25: 43740 | I25: =IF(Detalle!B379>=0.3,"OK · registrar",IF(Detalle!B379>=0.2,"Margen abril <30%","Margen abril <20% · subir objetivo o renegociar"))&" · P6 doble (real); abril sin consumo" -> Margen abril <20% · subir objetivo o renegociar · P6 doble (real); abril sin consumo
A26: 8732 | B26: C02430 | C26: CINDY DEPERE | D26: Naturgy | E26: =Detalle!B398 -> 0.26203771 | F26: =IF(Detalle!B398>=0.3,"APROBAR",IF(Detalle!B398>=0.2,"REVISAR","RECHAZAR")) -> REVISAR | G26: 0.31 | H26: 14442.13 | I26: =IF(Detalle!B398>=0.3,"OK · registrar",IF(Detalle!B398>=0.2,"Margen abril <30%","Margen abril <20% · subir objetivo o renegociar"))&" · Excedentes solares NO compensados" -> Margen abril <30% · Excedentes solares NO compensados
A27: 8733 | B27: C03410 | C27: NORAY PUERTO 2012 S.L. | D27: Naturgy | E27: =Detalle!B416 -> 0.18029709 | F27: =IF(Detalle!B416>=0.3,"APROBAR",IF(Detalle!B416>=0.2,"REVISAR","RECHAZAR")) -> RECHAZAR | G27: 0.326 | H27: 5854.69 | I27: =IF(Detalle!B416>=0.3,"OK · registrar",IF(Detalle!B416>=0.2,"Margen abril <30%","Margen abril <20% · subir objetivo o renegociar"))&"" -> Margen abril <20% · subir objetivo o renegociar
A28: 8734 | B28: C01820 | C28: PIZZERIA TIGER, S.L. | D28: Naturgy | E28: =Detalle!B434 -> 0.21443777 | F28: =IF(Detalle!B434>=0.3,"APROBAR",IF(Detalle!B434>=0.2,"REVISAR","RECHAZAR")) -> REVISAR | G28: 0.347 | H28: 33692.13 | I28: =IF(Detalle!B434>=0.3,"OK · registrar",IF(Detalle!B434>=0.2,"Margen abril <30%","Margen abril <20% · subir objetivo o renegociar"))&"" -> Margen abril <30%
A29: 8735 | B29: C02700 | C29: TALLERES MARTINEZ JAVEA SL | D29: Repsol | E29: =Detalle!B452 -> 0.047489346 | F29: =IF(Detalle!B452>=0.3,"APROBAR",IF(Detalle!B452>=0.2,"REVISAR","RECHAZAR")) -> RECHAZAR | G29: 0.129 | H29: 14832.89 | I29: =IF(Detalle!B452>=0.3,"OK · registrar",IF(Detalle!B452>=0.2,"Margen abril <30%","Margen abril <20% · subir objetivo o renegociar"))&"" -> Margen abril <20% · subir objetivo o renegociar
A30: 8737 | B30: C00740 | C30: PIZZERIA ORBA, S.L. | D30: Naturgy | E30: =Detalle!B470 -> 0.20018502 | F30: =IF(Detalle!B470>=0.3,"APROBAR",IF(Detalle!B470>=0.2,"REVISAR","RECHAZAR")) -> REVISAR | G30: 0.314 | H30: 82412.04 | I30: =IF(Detalle!B470>=0.3,"OK · registrar",IF(Detalle!B470>=0.2,"Margen abril <30%","Margen abril <20% · subir objetivo o renegociar"))&"" -> Margen abril <30%
A31: 8738 | B31: C02620 | C31: JAVEA PADEL & Tenis SL | D31: Naturgy | E31: =Detalle!B488 -> 0.16668595 | F31: =IF(Detalle!B488>=0.3,"APROBAR",IF(Detalle!B488>=0.2,"REVISAR","RECHAZAR")) -> RECHAZAR | G31: 0.324 | H31: 40860.13 | I31: =IF(Detalle!B488>=0.3,"OK · registrar",IF(Detalle!B488>=0.2,"Margen abril <30%","Margen abril <20% · subir objetivo o renegociar"))&"" -> Margen abril <20% · subir objetivo o renegociar
A33: Margen abril editable en TODAS (celda amarilla en Detalle). Margen hist., cobrado y mejor/peor mes vienen de HOJA TTVA LUZ por CUPS.

Sheet Detalle
A1: Factura 8544 · C02330 · ORENCO 2019, S.L. | I1: ES0021000001197056KH · Naturgy · 01/04/26 a 30/04/26 · PC real leído: 01MAR_31MAR26 (P2/P3/P6) + plan fijo | R1: HISTÓRICO DEL CUPS · HOJA TTVA LUZ
A2: Concepto | B2: PENDIENTE (sin registrar) | H2: MES ANTERIOR · Fact.6296 (01/03/26 a 31/03/26) | L2: AÑO ANTERIOR · Fact.4508 (01/04/25 a 30/04/25) | R2: Cobrado total: 40.716 €
B3: Cant | C3: Días | D3: PC real | E3: PV | F3: Importe | H3: Cant | I3: PV | J3: Importe | L3: Cant | M3: PV | N3: Importe | R3: Pagado total: 29.523 €
A4: P1 Potencia | B4: 30 | C4: 30 | D4: 1.73784 | E4: 2.5542 | F4: =ROUND(B4*E4,2) -> 76.63 | H4: 30 | I4: 2.5542 | J4: =ROUND(H4*I4,2) -> 76.63 | L4: 30 | M4: 2.5542 | N4: =ROUND(L4*M4,2) -> 76.63 | R4: DIF: 11.193 € · Margen hist.: 27.5%
A5: P2 Potencia | B5: 30 | C5: 30 | D5: 0.9357 | E5: 1.37733 | F5: =ROUND(B5*E5,2) -> 41.32 | H5: 30 | I5: 1.37733 | J5: =ROUND(H5*I5,2) -> 41.32 | L5: 30 | M5: 1.37733 | N5: =ROUND(L5*M5,2) -> 41.32 | R5: Mejor mes: 2024-06 · 3.014 € · margen 56%
A6: P3 Potencia | B6: 30 | C6: 30 | D6: 0.43137 | E6: 0.62868 | F6: =ROUND(B6*E6,2) -> 18.86 | H6: 30 | I6: 0.62868 | J6: =ROUND(H6*I6,2) -> 18.86 | L6: 30 | M6: 0.62868 | N6: =ROUND(L6*M6,2) -> 18.86 | R6: Peor mes: 2024-11 · 701 € · margen 39%
A7: P4 Potencia | B7: 30 | C7: 30 | D7: 0.38244 | E7: 0.5561 | F7: =ROUND(B7*E7,2) -> 16.68 | H7: 30 | I7: 0.5561 | J7: =ROUND(H7*I7,2) -> 16.68 | L7: 30 | M7: 0.5561 | N7: =ROUND(L7*M7,2) -> 16.68 | R7: ⚠ Consumo en P1/P2 (calendario inactivo) → consolidado a P4/P5/P6
A8: P5 Potencia | B8: 30 | C8: 30 | D8: 0.26964 | E8: 0.3868 | F8: =ROUND(B8*E8,2) -> 11.6 | H8: 30 | I8: 0.3868 | J8: =ROUND(H8*I8,2) -> 11.6 | L8: 30 | M8: 0.3868 | N8: =ROUND(L8*M8,2) -> 11.6 | R8: Importe mensual cobrado (€) · últimos 24 meses
A9: P6 Potencia | B9: 30 | C9: 30 | D9: 0.18156 | E9: 0.2653 | F9: =ROUND(B9*E9,2) -> 7.96 | H9: 30 | I9: 0.2653 | J9: =ROUND(H9*I9,2) -> 7.96 | L9: 30 | M9: 0.2653 | N9: =ROUND(L9*M9,2) -> 7.96
A10: P4 Energía | B10: =IF($P$10="",2517.101,ROUND(2517.101*((1087.3487/(1-$P$10))-173.05)/1151.35,2)) -> 2517.101 | D10: 0.121236 | E10: 0.139 | F10: =ROUND(B10*E10,2) -> 349.88 | H10: 2317.101 | I10: 0.139 | J10: =ROUND(H10*I10,2) -> 322.08 | L10: 1937.42 | M10: 0.145 | N10: =ROUND(L10*M10,2) -> 280.93 | O10: Margen objetivo (edita el % aquí) ▶
A11: P5 Energía | B11: =IF($P$10="",2364.265,ROUND(2364.265*((1087.3487/(1-$P$10))-173.05)/1151.35,2)) -> 2364.265 | D11: 0.114444 | E11: 0.138 | F11: =ROUND(B11*E11,2) -> 326.27 | H11: 2064.265 | I11: 0.138 | J11: =ROUND(H11*I11,2) -> 284.87 | L11: 1611.579 | M11: 0.139 | N11: =ROUND(L11*M11,2) -> 224.01 | O11: Cant. P4/P5/P6 suben en proporción
A12: P6 Energía | B12: =IF($P$10="",3683.741,ROUND(3683.741*((1087.3487/(1-$P$10))-173.05)/1151.35,2)) -> 3683.741 | D12: 0.106808 | E12: 0.129 | F12: =ROUND(B12*E12,2) -> 475.2 | H12: 3383.741 | I12: 0.129 | J12: =ROUND(H12*I12,2) -> 436.5 | L12: 2928.76 | M12: 0.139 | N12: =ROUND(L12*M12,2) -> 407.1 | O12: para cumplir ese margen
A13: Alquiler contador | B13: 1 | D13: 17.615 | E13: 17.615 | F13: =ROUND(B13*E13,2) -> 17.62 | H13: 1 | I13: 17.615 | J13: =ROUND(H13*I13,2) -> 17.62 | L13: 1 | M13: 17.615 | N13: =ROUND(L13*M13,2) -> 17.62
A14: Bono social | B14: 30 | D14: 0.01912 | E14: 0.01912 | F14: =ROUND(B14*E14,2) -> 0.57 | H14: 30 | I14: 0.01274 | J14: =ROUND(H14*I14,2) -> 0.38 | L14: 30 | M14: 0.01274 | N14: =ROUND(L14*M14,2) -> 0.38
A15: Tasa eléctrica | B15: 71.99 | D15: 1 | E15: 1 | F15: =ROUND(B15*E15,2) -> 71.99 | H15: 66.49 | I15: 1 | J15: =ROUND(H15*I15,2) -> 66.49 | L15: 62.66 | M15: 1 | N15: =ROUND(L15*M15,2) -> 62.66
A16: TOTAL c/IVA | F16: =ROUND((SUM(F4:F15)-F15)*1.21+F15,2) -> 1696.52 | J16: =ROUND((SUM(J4:J15)-J15)*1.21+J15,2) -> 1560.24 | N16: =ROUND((SUM(N4:N15)-N15)*1.21+N15,2) -> 1397.4
A17: MARGEN sin registrar | B17: =(SUM(F4:F12)-1087.3487)/SUM(F4:F12) -> 0.17898769 | L17: =IF(B17>=0.3,"APROBAR",IF(B17>=0.2,"REVISAR","RECHAZAR")) -> RECHAZAR
A19: Factura 8545 · C01200 · SOLUCIONES GASTRONÓMICAS DE JAVEA 2014, S.L. | I19: ES0021000001209594ZK · Naturgy · 01/04/26 a 30/04/26 · PC maestro (=factura real, verificado) | R19: HISTÓRICO DEL CUPS · HOJA TTVA LUZ
A20: Concepto | B20: PENDIENTE (sin registrar) | H20: MES ANTERIOR · Fact.6297 (01/03/26 a 31/03/26) | L20: AÑO ANTERIOR · Fact.4514 (01/04/25 a 30/04/25) | R20: Cobrado total: 53.718 €
B21: Cant | C21: Días | D21: PC real | E21: PV | F21: Importe | H21: Cant | I21: PV | J21: Importe | L21: Cant | M21: PV | N21: Importe | R21: Pagado total: 40.613 €
A22: P1 Potencia | B22: 17.32 | C22: 30 | D22: 1.73784 | E22: 1.999 | F22: =ROUND(B22*E22,2) -> 34.62 | H22: 17.32 | I22: 1.999 | J22: =ROUND(H22*I22,2) -> 34.62 | L22: 17.32 | M22: 2.5542 | N22: =ROUND(L22*M22,2) -> 44.24 | R22: DIF: 13.105 € · Margen hist.: 24.4%
A23: P2 Potencia | B23: 17.32 | C23: 30 | D23: 0.9357 | E23: 1.811 | F23: =ROUND(B23*E23,2) -> 31.37 | H23: 17.32 | I23: 1.811 | J23: =ROUND(H23*I23,2) -> 31.37 | L23: 17.32 | M23: 1.3773 | N23: =ROUND(L23*M23,2) -> 23.85 | R23: Mejor mes: 2024-08 · 2.606 € · margen 23%
A24: P3 Potencia | B24: 17.32 | C24: 30 | D24: 0.43137 | E24: 0.6161 | F24: =ROUND(B24*E24,2) -> 10.67 | H24: 17.32 | I24: 0.6161 | J24: =ROUND(H24*I24,2) -> 10.67 | L24: 17.32 | M24: 0.6286 | N24: =ROUND(L24*M24,2) -> 10.89 | R24: Peor mes: 2023-01 · 446 € · margen 25%
A25: P4 Potencia | B25: 17.32 | C25: 30 | D25: 0.38244 | E25: 0.5551 | F25: =ROUND(B25*E25,2) -> 9.61 | H25: 17.32 | I25: 0.5551 | J25: =ROUND(H25*I25,2) -> 9.61 | L25: 17.32 | M25: 0.5561 | N25: =ROUND(L25*M25,2) -> 9.63 | R25: ⚠ Consumo en P1/P2 (calendario inactivo) → consolidado a P4/P5/P6
A26: P5 Potencia | B26: 17.32 | C26: 30 | D26: 0.26964 | E26: 0.595 | F26: =ROUND(B26*E26,2) -> 10.31 | H26: 17.32 | I26: 0.595 | J26: =ROUND(H26*I26,2) -> 10.31 | L26: 17.32 | M26: 0.3868 | N26: =ROUND(L26*M26,2) -> 6.7 | R26: Importe mensual cobrado (€) · últimos 24 meses
A27: P6 Potencia | B27: 17.32 | C27: 30 | D27: 0.18156 | E27: 0.4523 | F27: =ROUND(B27*E27,2) -> 7.83 | H27: 17.32 | I27: 0.4523 | J27: =ROUND(H27*I27,2) -> 7.83 | L27: 17.32 | M27: 0.2653 | N27: =ROUND(L27*M27,2) -> 4.59
A28: P4 Energía | B28: =IF($P$28="",1691.432,ROUND(1691.432*((803.9614/(1-$P$28))-104.41)/912.75,2)) -> 1691.432 | D28: 0.121236 | E28: 0.149 | F28: =ROUND(B28*E28,2) -> 252.02 | H28: 1474.716 | I28: 0.15 | J28: =ROUND(H28*I28,2) -> 221.21 | L28: 1570.18 | M28: 0.16 | N28: =ROUND(L28*M28,2) -> 251.23 | O28: Margen objetivo (edita el % aquí) ▶
A29: P5 Energía | B29: =IF($P$28="",2156.035,ROUND(2156.035*((803.9614/(1-$P$28))-104.41)/912.75,2)) -> 2156.035 | D29: 0.114444 | E29: 0.14 | F29: =ROUND(B29*E29,2) -> 301.84 | H29: 1814.66 | I29: 0.149 | J29: =ROUND(H29*I29,2) -> 270.38 | L29: 1034.274 | M29: 0.155 | N29: =ROUND(L29*M29,2) -> 160.31 | O29: Cant. P4/P5/P6 suben en proporción
A30: P6 Energía | B30: =IF($P$28="",2658.43,ROUND(2658.43*((803.9614/(1-$P$28))-104.41)/912.75,2)) -> 2658.43 | D30: 0.106808 | E30: 0.135 | F30: =ROUND(B30*E30,2) -> 358.89 | H30: 2225.184 | I30: 0.139 | J30: =ROUND(H30*I30,2) -> 309.3 | L30: 2165.73 | M30: 0.135 | N30: =ROUND(L30*M30,2) -> 292.37 | O30: para cumplir ese margen
A31: Alquiler contador | B31: 1 | D31: 17.615 | E31: 17.615 | F31: =ROUND(B31*E31,2) -> 17.62 | H31: 1 | I31: 17.615 | J31: =ROUND(H31*I31,2) -> 17.62 | L31: 1 | M31: 17.615 | N31: =ROUND(L31*M31,2) -> 17.62
A32: Bono social | B32: 5 | D32: 0.01912 | E32: 0.01912 | F32: =ROUND(B32*E32,2) -> 0.1 | H32: 5 | I32: 0.01912 | J32: =ROUND(H32*I32,2) -> 0.1 | L32: 30 | M32: 0.01274 | N32: =ROUND(L32*M32,2) -> 0.38
A33: Tasa eléctrica | B33: 59.26 | D33: 1 | E33: 1 | F33: =ROUND(B33*E33,2) -> 59.26 | H33: 49.46 | I33: 1 | J33: =ROUND(H33*I33,2) -> 49.46 | L33: 44 | M33: 1 | N33: =ROUND(L33*M33,2) -> 44
A34: TOTAL c/IVA | F34: =ROUND((SUM(F22:F33)-F33)*1.21+F33,2) -> 1311.46 | J34: =ROUND((SUM(J22:J33)-J33)*1.21+J33,2) -> 1166.31 | N34: =ROUND((SUM(N22:N33)-N33)*1.21+N33,2) -> 1038.39
A35: MARGEN sin registrar | B35: =(SUM(F22:F30)-803.9614)/SUM(F22:F30) -> 0.20960183 | L35: =IF(B35>=0.3,"APROBAR",IF(B35>=0.2,"REVISAR","RECHAZAR")) -> REVISAR
A37: Factura 8546 · C03270 · LULU BEACH CLUB JAVEA SL | I37: ES0021000001205457LR · Naturgy · 01/04/26 a 30/04/26 · PC maestro (=factura real, verificado) | R37: HISTÓRICO DEL CUPS · HOJA TTVA LUZ
A38: Concepto | B38: PENDIENTE (sin registrar) | H38: MES ANTERIOR (s/d) | L38: AÑO ANTERIOR (s/d) | R38: Cobrado total: 12.272 €
B39: Cant | C39: Días | D39: PC real | E39: PV | F39: Importe | H39: Cant | I39: PV | J39: Importe | L39: Cant | M39: PV | N39: Importe | R39: Pagado total: 9.764 €
A40: P1 Potencia | B40: 37 | C40: 30 | D40: 1.73784 | E40: 1.74 | F40: =ROUND(B40*E40,2) -> 64.38 | R40: DIF: 2.509 € · Margen hist.: 20.4%
A41: P2 Potencia | B41: 37 | C41: 30 | D41: 0.9357 | E41: 0.94 | F41: =ROUND(B41*E41,2) -> 34.78 | R41: Mejor mes: 2026-05 · 3.747 € · margen 22%
A42: P3 Potencia | B42: 37 | C42: 30 | D42: 0.43137 | E42: 0.43 | F42: =ROUND(B42*E42,2) -> 15.91 | R42: Peor mes: 2026-02 · 1.625 € · margen 27%
...

Sheet _series
A1: nf | B1: 2024-07 | C1: 2024-08 | D1: 2024-09 | E1: 2024-10 | F1: 2024-11 | G1: 2024-12 | H1: 2025-01 | I1: 2025-02 | J1: 2025-03 | K1: 2025-04 | L1: 2025-05 | M1: 2025-06 | N1: 2025-07 | O1: 2025-08 | P1: 2025-09 | Q1: 2025-10 | R1: 2025-11 | S1: 2025-12 | T1: 2026-01 | U1: 2026-02 | V1: 2026-03 | W1: 2026-04 | X1: 2026-05 | Y1: 2026-06
A2: 8544 | B2: 1823.2 | C2: 2200.79 | D2: 1506.86 | E2: 1294.73 | F2: 701.24 | G2: 2057.58 | H2: 704.65 | I2: 1131.33 | J2: 1195.22 | K2: 1397.39 | L2: 1489.78 | M2: 1604.92 | N2: 2264.68 | O2: 2392.22 | P2: 1906.5 | Q2: 1541.7 | R2: 1553.06 | S2: 1623.98 | T2: 1669.87 | U2: 1287.26 | V2: 1560.23 | W2: 1696.52 | X2: 1398.99 | Y2: 1699.39
A3: 8545 | B3: 2278.23 | C3: 2606.49 | D3: 1372.78 | E3: 1218.04 | F3: 852.42 | G3: 892.96 | H3: 526.46 | I3: 703.02 | J3: 973.88 | K3: 1071.5 | L3: 1198.45 | M3: 1352.91 | N3: 2137.78 | O3: 2576.37 | P3: 1966.13 | Q3: 1508.21 | R3: 982.22 | S3: 980.76 | T3: 639.12 | U3: 1081.39 | V3: 1166.31 | W3: 1408.31 | X3: 1317.52 | Y3: 0
A4: 8546 | B4: 0 | C4: 0 | D4: 0 | E4: 0 | F4: 0 | G4: 0 | H4: 0 | I4: 0 | J4: 0 | K4: 0 | L4: 0 | M4: 0 | N4: 0 | O4: 0 | P4: 0 | Q4: 0 | R4: 0 | S4: 0 | T4: 0 | U4: 1625.21 | V4: 3262.26 | W4: 3637.92 | X4: 3747.07 | Y4: 0
A5: 8547 | B5: 4696.57 | C5: 5119.32 | D5: 3940.09 | E5: 4434.05 | F5: 4230.84 | G5: 4056.83 | H5: 3691.35 | I5: 4434.05 | J5: 4606.23 | K5: 3691.35 | L5: 3472.32 | M5: 3278.22 | N5: 4267.48 | O5: 4424.02 | P5: 3939.03 | Q5: 3404.76 | R5: 3733.87 | S5: 3769.58 | T5: 2917.21 | U5: 3522.69 | V5: 3557.98 | W5: 3087.33 | X5: 3133.52 | Y5: 3743.04
A6: 8564 | B6: 643.79 | C6: 476.53 | D6: 592.3 | E6: 631.06 | F6: 457.49 | G6: 578.16 | H6: 596.33 | I6: 602.79 | J6: 791.23 | K6: 624.49 | L6: 601.33 | M6: 711.31 | N6: 738.16 | O6: 605.43 | P6: 803.47 | Q6: 816.36 | R6: 572.69 | S6: 690.5 | T6: 712.22 | U6: 695.09 | V6: 791.23 | W6: 741.17 | X6: 782.58 | Y6: 755.25
A7: 8565 | B7: 632.44 | C7: 592.69 | D7: 610.04 | E7: 632.66 | F7: 637.18 | G7: 207.37 | H7: 706.19 | I7: 645.52 | J7: 899.33 | K7: 591.1 | L7: 643.89 | M7: 696.92 | N7: 731.73 | O7: 688.65 | P7: 794.97 | Q7: 824.16 | R7: 684.8 | S7: 331.28 | T7: 819.21 | U7: 753.83 | V7: 1018.62 | W7: 685.61 | X7: 741.79 | Y7: 789.76
A8: 8566 | B8: 524.5 | C8: 166.78 | D8: 444.46 | E8: 345.59 | F8: 0 | G8: 233.91 | H8: 294.11 | I8: 270.48 | J8: 383.23 | K8: 290.33 | L8: 336.88 | M8: 502.61 | N8: 634.9 | O8: 239.55 | P8: 628.5 | Q8: 440.92 | R8: 411.49 | S8: 407.39 | T8: 420.96 | U8: 391.83 | V8: 427.24 | W8: 354.48 | X8: 412.63 | Y8: 593.22
A9: 8567 | B9: 4475.16 | C9: 4612.54 | D9: 3701.38 | E9: 4561.47 | F9: 3334.09 | G9: 3216.6 | H9: 2924.41 | I9: 2743.54 | J9: 3702.5 | K9: 3817.43 | L9: 3300.04 | M9: 2798.1 | N9: 3784.48 | O9: 3716.14 | P9: 3334.45 | Q9: 3275.16 | R9: 3190.07 | S9: 2956.24 | T9: 2736.06 | U9: 2890.35 | V9: 3365.79 | W9: 2721.04 | X9: 2640.22 | Y9: 3260.09
A10: 8578 | B10: 151.82 | C10: 199.06 | D10: 183.84 | E10: 178.12 | F10: 184.03 | G10: 163.02 | H10: 136.55 | I10: 104.41 | J10: 98.7 | K10: 40.05 | L10: 67.35 | M10: 65.71 | N10: 361.06 | O10: 201.13 | P10: 85.6 | Q10: 63.93 | R10: 60.72 | S10: 51.57 | T10: 43.55 | U10: 40.37 | V10: 82.31 | W10: 38.53 | X10: 39.81 | Y10: 0
A11: 8615 | B11: 1167.19 | C11: 1131.86 | D11: 610.86 | E11: 553.94 | F11: 544.65 | G11: 727.09 | H11: 952.35 | I11: 581.27 | J11: 746.2 | K11: 543.77 | L11: 442.06 | M11: 643.81 | N11: 881.89 | O11: 963.15 | P11: 800.92 | Q11: 588.39 | R11: 478.95 | S11: 812.61 | T11: 783.67 | U11: 595.95 | V11: 634.87 | W11: 433.2 | X11: 544.11 | Y11: 0
A12: 8629 | B12: 128.85 | C12: 119.74 | D12: 120.37 | E12: 126 | F12: 121.75 | G12: 129.12 | H12: 118.2 | I12: 116.61 | J12: 118.21 | K12: 118.11 | L12: 120.31 | M12: 110.46 | N12: 126.3 | O12: 120.84 | P12: 118.41 | Q12: 110.34 | R12: 143.28 | S12: 123.63 | T12: 117.54 | U12: 119.84 | V12: 122.01 | W12: 115.84 | X12: 0 | Y12: 0
A13: 8635 | B13: 1506.8 | C13: 1792.99 | D13: 833.07 | E13: 766.01 | F13: 194.02 | G13: 665.19 | H13: 676.36 | I13: 603.95 | J13: 730.96 | K13: 678.97 | L13: 774.09 | M13: 774.72 | N13: 1594.97 | O13: 1863.52 | P13: 1379.87 | Q13: 902.28 | R13: 243.48 | S13: 790.46 | T13: 762.17 | U13: 615.97 | V13: 542.6 | W13: 641.56 | X13: 747.69 | Y13: 0
... A28: 8738 | B28: 0 | C28: 0 | D28: 0 | E28: 0 | F28: 1197.18 | G28: 1865.97 | H28: 1723.16 | I28: 1570.31 | J28: 1432.73 | K28: 1817.32 | L28: 1955.83 | M28: 2235.47 | N28: 2825.24 | O28: 3443.22 | P28: 3178.08 | Q28: 2134.16 | R28: 1883.16 | S28: 1916.12 | T28: 1372.39 | U28: 2844.42 | V28: 2594.23 | W28: 2436.29 | X28: 2434.85 | Y28: 0
